Workbook

Sheet サマリー
B1: 大型OEMリサーチ（神田式）サマリー 2026-09-24
B3: 結論
B4: 1. 前回の40候補を同じ条件（手数料15.4%/10.4%・広告10%・返品4%・保管・出荷作業・送料・関税込み）で試算すると、利益率15%以上は8商品。
B5: 2. 月利100万円に最も近いのは『大型宅配ボックス』と『大型猫用キャットタワー』。単品では必要月販が約350〜360個のため、サイズ・色展開と楽天・Yahoo!併売で到達させる設計。
B6: 3. 前回上位10のうち、タイヤラック（実勢¥5,720〜6,980）・45Lごみ箱ラック・梱包作業台は実勢価格か大型送料で不成立。猫トイレ収納・リネンカート・ポッティングベンチ・ステンレスワゴンは利益率10〜15%の『条件付き』（天瞳の送料・実見積しだい）。
B7: 4. 大型品の損益は国内送料と立米単価で大きく変わる。天瞳の送料資料の数値を『前提条件』に入れると全表が再計算され、『15%達成の国内送料上限』で合否がすぐ分かる。
B8: データについて
B9: ・Amazon.co.jp／1688.com の商品ページは、この作業環境のネットワーク制限で直接開けなかった。競合の価格・仕様・口コミは検索結果で確認できた範囲（出典付き）、1688単価・梱包寸法・月販は推定（黄色セル＝要上書き）。
B10: ・添付のリサーチ表テンプレート・商品リスト・送料資料は本環境から参照できなかったため、列構成は一般的な中国輸入OEMリサーチ表に合わせた。
B12: 利益率15%以上の厳選8商品（リサーチ表から自動参照）
B13: 商品名 | C13: 販売価格 | D13: 利益/個 | E13: 利益率 | F13: 月利（想定月販） | G13: 想定月販 | H13: 月利100万に必要な月販 | I13: 判定
B14: ='リサーチ表(15%以上)'!B5 -> 大型宅配ボックス（戸建て・組立式スチール110L） | C14: ='リサーチ表(15%以上)'!J5 -> 19800 | D14: ='リサーチ表(15%以上)'!AJ5 -> 2764.176 | E14: ='リサーチ表(15%以上)'!AK5 -> 0.15356533 | F14: ='リサーチ表(15%以上)'!AP5 -> 691044 | G14: ='リサーチ表(15%以上)'!AN5 -> 250 | H14: ='リサーチ表(15%以上)'!AQ5 -> 362 | I14: ='リサーチ表(15%以上)'!AT5 -> ◎ 15%以上
B15: ='リサーチ表(15%以上)'!B6 -> 大型猫用キャットタワー（180cm・極太支柱・揺れ対策） | C15: ='リサーチ表(15%以上)'!J6 -> 17980 | D15: ='リサーチ表(15%以上)'!AJ6 -> 2851.2229 | E15: ='リサーチ表(15%以上)'!AK6 -> 0.17443522 | F15: ='リサーチ表(15%以上)'!AP6 -> 427683.44 | G15: ='リサーチ表(15%以上)'!AN6 -> 150 | H15: ='リサーチ表(15%以上)'!AQ6 -> 351 | I15: ='リサーチ表(15%以上)'!AT6 -> ◎ 15%以上
B16: ='リサーチ表(15%以上)'!B7 -> ゴルフバッグ2台収納ラック（固定ベルト・洗える泥受け） | C16: ='リサーチ表(15%以上)'!J7 -> 12980 | D16: ='リサーチ表(15%以上)'!AJ7 -> 2913.305 | E16: ='リサーチ表(15%以上)'!AK7 -> 0.24689025 | F16: ='リサーチ表(15%以上)'!AP7 -> 174798.3 | G16: ='リサーチ表(15%以上)'!AN7 -> 60 | H16: ='リサーチ表(15%以上)'!AQ7 -> 344 | I16: ='リサーチ表(15%以上)'!AT7 -> ◎ 15%以上
B17: ='リサーチ表(15%以上)'!B8 -> 自転車2台スタンド（自立式・室内縦置き） | C17: ='リサーチ表(15%以上)'!J8 -> 9980 | D17: ='リサーチ表(15%以上)'!AJ8 -> 1728.4255 | E17: ='リサーチ表(15%以上)'!AK8 -> 0.19050782 | F17: ='リサーチ表(15%以上)'!AP8 -> 172842.55 | G17: ='リサーチ表(15%以上)'!AN8 -> 100 | H17: ='リサーチ表(15%以上)'!AQ8 -> 579 | I17: ='リサーチ表(15%以上)'!AT8 -> ◎ 15%以上
B18: ='リサーチ表(15%以上)'!B9 -> A3複合機対応プリンターワゴン（横揺れ防止・大径キャスター） | C18: ='リサーチ表(15%以上)'!J9 -> 10980 | D18: ='リサーチ表(15%以上)'!AJ9 -> 1925.4836 | E18: ='リサーチ表(15%以上)'!AK9 -> 0.19289909 | F18: ='リサーチ表(15%以上)'!AP9 -> 115529.02 | G18: ='リサーチ表(15%以上)'!AN9 -> 60 | H18: ='リサーチ表(15%以上)'!AQ9 -> 520 | I18: ='リサーチ表(15%以上)'!AT9 -> ◎ 15%以上
B19: ='リサーチ表(15%以上)'!B10 -> 洗濯機上ランドリーラック（蛇口・防水パン干渉ゼロ設計） | C19: ='リサーチ表(15%以上)'!J10 -> 7980 | D19: ='リサーチ表(15%以上)'!AJ10 -> 1439.5391 | E19: ='リサーチ表(15%以上)'!AK10 -> 0.19843271 | F19: ='リサーチ表(15%以上)'!AP10 -> 287907.82 | G19: ='リサーチ表(15%以上)'!AN10 -> 200 | H19: ='リサーチ表(15%以上)'!AQ10 -> 695 | I19: ='リサーチ表(15%以上)'!AT10 -> ◎ 15%以上
B20: ='リサーチ表(15%以上)'!B11 -> ボール収納ワゴン（学校・クラブ向け・キャスター付き） | C20: ='リサーチ表(15%以上)'!J11 -> 9980 | D20: ='リサーチ表(15%以上)'!AJ11 -> 1660.9255 | E20: ='リサーチ表(15%以上)'!AK11 -> 0.18306794 | F20: ='リサーチ表(15%以上)'!AP11 -> 66437.018 | G20: ='リサーチ表(15%以上)'!AN11 -> 40 | H20: ='リサーチ表(15%以上)'!AQ11 -> 603 | I20: ='リサーチ表(15%以上)'!AT11 -> ◎ 15%以上
B21: ='リサーチ表(15%以上)'!B12 -> サロン収納ワゴン（髪が絡まないキャスター・ドライヤーホルダー） | C21: ='リサーチ表(15%以上)'!J12 -> 7980 | D21: ='リサーチ表(15%以上)'!AJ12 -> 1310.7891 | E21: ='リサーチ表(15%以上)'!AK12 -> 0.18068521 | F21: ='リサーチ表(15%以上)'!AP12 -> 78647.345 | G21: ='リサーチ表(15%以上)'!AN12 -> 60 | H21: ='リサーチ表(15%以上)'!AQ12 -> 763 | I21: ='リサーチ表(15%以上)'!AT12 -> ◎ 15%以上
B23: 次にやること
B24: ① 天瞳の送料資料（立米単価・サイズ別の国内送料・保管料・出荷作業料）を『前提条件』の黄色セルに入力 → 判定を確定
B25: ② 上位2商品（宅配ボックス・キャットタワー）の1688見積を各3社（単価・MOQ・梱包寸法・重量・耐荷重試験）→ 黄色セルを上書き
B26: ③ Keepa／セラースプライトで競合上位3品の月販・価格推移を確認 → 想定月販を更新
B27: ④ Amazonの星1〜3レビューを精読し、『レビュー分析』の要確認行を埋める → 付加価値の仕様書へ
B28: ⑤ △条件付き（猫トイレ収納・ステンレスワゴン・屋外ごみ保管ボックス等）を天瞳の送料で再判定
B30: 凡例：青字・黄色＝入力（推定含む）／黒字＝計算式／緑字＝他シート参照／黄色（濃）＝天瞳資料で必ず差し替える前提

Sheet リサーチ表(15%以上)
A1: 大型OEM リサーチ表（神田式）― 利益率15%以上に厳選 作成日：2026-09-24
A2: 青字・黄色セル＝入力（推定値を含む）／黒字＝計算式／緑字＝他シート参照。利益率＝利益÷税抜売上。利益は広告費・返品引当・保管料・出荷作業料まで控除後（固定費は別）。データ確度 A=商品ページで確認／B=検索結果経由で確認／C=推定（要実測）。1688単価・梱包寸法・月販はC（推定）です。
A3: 基本情報・競合（Amazon等） | J3: 売価 | K3: 仕入（1688）・梱包・物流 | Z3: 着地原価（1個） | AD3: 損益（1個あたり・税抜） | AN3: 月間シミュレーション | AR3: 感応度・判定 | AU3: 差別化・レビュー分析
A4: 優先順位 | B4: 商品名（OEM企画） | C4: コンセプト（狙い） | D4: Amazonカテゴリ | E4: 販売手数料率 | F4: 主要競合（商品・スペック） | G4: 競合URL | H4: 競合価格・根拠 | I4: Amazon検索リンク | J4: 想定販売価格（税込・円） | K4: 1688検索キーワード（中国語） | L4: 1688検索リンク | M4: 想定仕入単価（元）※推定 | N4: 付加価値の追加コスト（円） | O4: 梱包 縦(cm) | P4: 梱包 横(cm) | Q4: 梱包 高さ(cm) | R4: 梱包重量(kg) | S4: 3辺合計(cm) | T4: 容積(m³) | U4: 配送区分No | V4: 国内配送サイズ | W4: 国内送料（円） | X4: FBA区分（参考） | Y4: 関税率 | Z4: 仕入原価（円） | AA4: 国際送料（円） | AB4: 関税（円） | AC4: 着地原価（円） | AD4: 税抜売上（円） | AE4: 販売手数料（円） | AF4: 広告費（円） | AG4: 返品・破損引当（円） | AH4: 保管料（円） | AI4: 出荷作業料（円） | AJ4: 利益（円/個） | AK4: 利益率（税抜売上比） | AL4: 広告前利益率 | AM4: ROI（利益÷着地原価） | AN4: 想定月販（個）※推定 | AO4: 月商（税込・円） | AP4: 月利（円） | AQ4: 月利100万に必要な月販（個） | AR4: 15%達成の国内送料上限（円） | AS4: 15%達成の仕入単価上限（元） | AT4: 判定 | AU4: 付加価値（差別化）案 | AV4: 高評価ポイント（競合レビュー） | AW4: 改善要望（優先度付き） | AX4: 最優先の改善 | AY4: データ確度 | AZ4: 次の確認事項
A5: 1 | B5: 大型宅配ボックス（戸建て・組立式スチール110L） | C5: 置き配定着で需要が大きい戸建て用。組立式（ノックダウン）で梱包容積を完成品の約1/3に抑え、送料差で完成品の競合より高機能・同価格帯を実現 | D5: DIY・工具・ガーデン | E5: =IFERROR(INDEX('前提条件'!$B$20:$B$28,MATCH(D5,'前提条件'!$A$20:$A$28,0)),'前提条件'!$B$20) -> 0.154 | F5: タンスのゲン ポスト一体型 108L/134L、COVELL 140L（完成品・投函口3・IP55）、ルスネコボックス、ポスミー | G5: https://store.shopping.yahoo.co.jp/tansu/17600169.html | H5: タンスのゲン 134L 旧モデル ¥17,999（Yahoo!商品名の表記）／COVELL 140L は価格未確認 | I5: Amazonで検索 | J5: 19800 | K5: 快递箱 户外 别墅 包裹箱 带信箱 大容量 组装 | L5: 1688で検索 | M5: 200 | N5: 500 | O5: 108 | P5: 52 | Q5: 16 | R5: 20 | S5: =O5+P5+Q5 -> 176 | T5: =O5*P5*Q5/1000000 -> 0.089856 | U5: =MAX(MATCH(S5,'前提条件'!$C$34:$C$46,1),INDEX('前提条件'!$J$34:$J$41,MATCH(R5,'前提条件'!$H$34:$H$41,1))) -> 8 | V5: =INDEX('前提条件'!$B$34:$B$46,U5) -> 180サイズ | W5: =INDEX('前提条件'!$E$34:$E$46,U5)*'前提条件'!$B$7 -> 2200 | X5: =IF(AND(S5<=200,R5<=40),"大型以内",IF(AND(S5<=260,R5<=50),"特大型","FBA不可")) -> 大型以内 | Y5: 0 | Z5: =M5*'前提条件'!$B$4*(1+'前提条件'!$B$5) -> 5184 | AA5: =T5*'前提条件'!$B$6 -> 1078.272 | AB5: =(Z5+AA5)*Y5 -> 0 | AC5: =Z5+N5+AA5+AB5 -> 6762.272 | AD5: =J5/(1+'前提条件'!$B$13) -> 18000 | AE5: =J5*E5 -> 3049.2 | AF5: =AD5*'前提条件'!$B$8 -> 1800 | AG5: =AD5*'前提条件'!$B$9 -> 720 | AH5: =T5*'前提条件'!$B$10*'前提条件'!$B$11 -> 404.352 | AI5: ='前提条件'!$B$12 -> 300 | AJ5: =AD5-AE5-W5-AF5-AG5-AH5-AI5-AC5 -> 2764.176 | AK5: =IF(AD5>0,AJ5/AD5,0) -> 0.15356533 | AL5: =IF(AD5>0,(AJ5+AF5)/AD5,0) -> 0.25356533 | AM5: =IF(AC5>0,AJ5/AC5,0) -> 0.40876439 | AN5: 250 | AO5: =J5*AN5 -> 4950000 | AP5: =AJ5*AN5 -> 691044 | AQ5: =IF(AJ5>0,ROUNDUP('前提条件'!$B$15/AJ5,0),"赤字") -> 362 | AR5: =W5+(AJ5-'前提条件'!$B$14*AD5) -> 2264.176 | AS5: =M5+(AJ5-'前提条件'!$B$14*AD5)/('前提条件'!$B$4*(1+'前提条件'!$B$5)*(1+Y5)) -> 202.47593 | AT5: =IF(AK5>='前提条件'!$B$14,"◎ 15%以上",IF(AK5>='前提条件'!$B$16,"△ 条件付き","× 除外")) -> ◎ 15%以上 | AU5: ①組立式で梱包容積を完成品の約1/3（180サイズ）②アンカーボルト＋盗難防止ワイヤーの固定キット同梱③オートリセット式ダイヤル錠＋予備鍵④投函口3か所・複数投函・ダンパー付き上蓋⑤防水パッキン＋排水穴（IP55相当を目標）⑥印鑑ホルダー・反射ステッカー | AV5: 大容量で複数の荷物が届いても余裕／防水で天候を気にせず使える／組立不要・両開き扉で出し入れが楽／印鑑ホルダーで非対面受取／ベンチ兼用型も高評価 | AW5: 【高】軽い本体ごと盗まれる→アンカー固定が必須／【高】南京錠は破られやすい・ダイヤル番号が推測される→オートリセット錠／【高】傷から錆、鍵部の錆・電子錠の故障／【中】設置スペース・固定工事の手間／【低】届く箱が重い | AX5: 【高】盗難対策（固定キット同梱）と防錆（厚膜粉体塗装・ステンレス蝶番） | AY5: 競合・レビュー=B／原価・寸法・月販=C | AZ5: 1688で「组装式 快递箱」3社見積（板厚0.8mm以上・粉体塗装・投函口ダンパー）／防水試験の有無／上位3品の月販をセラースプライト・Keepaで確認
A6: 2 | B6: 大型猫用キャットタワー（180cm・極太支柱・揺れ対策） | C6: メインクーン等6kg超の大型猫・多頭飼い特化。極太支柱×重量ベース×転倒防止キットで「揺れない」を訴求し、単価¥17,980帯を狙う | D6: ペット用品 | E6: =IFERROR(INDEX('前提条件'!$B$20:$B$28,MATCH(D6,'前提条件'!$A$20:$A$28,0)),'前提条件'!$B$20) -> 0.154 | F6: PETEPELA スリム175cm（評価1,544件＝カテゴリ平均868件の178%）、FEANDREA 大型猫用（耐荷重90kg）、RAKU 木製183.5cm、Mwpo 057A、Heybly 180cm | G6: https://sakura-checker.jp/search/B099RYLG3S/ | H6: 180cm帯は¥11,980前後の例（楽天検索結果）。大型猫向け上位品の価格は未確認 | I6: Amazonで検索 | J6: 17980 | K6: 猫爬架 大型 缅因猫 粗柱 落地 180 | L6: 1688で検索 | M6: 170 | N6: 500 | O6: 82 | P6: 47 | Q6: 28 | R6: 24 | S6: =O6+P6+Q6 -> 157 | T6: =O6*P6*Q6/1000000 -> 0.107912 | U6: =MAX(MATCH(S6,'前提条件'!$C$34:$C$46,1),INDEX('前提条件'!$J$34:$J$41,MATCH(R6,'前提条件'!$H$34:$H$41,1))) -> 6 | V6: =INDEX('前提条件'!$B$34:$B$46,U6) -> 160サイズ | W6: =INDEX('前提条件'!$E$34:$E$46,U6)*'前提条件'!$B$7 -> 1450 | X6: =IF(AND(S6<=200,R6<=40),"大型以内",IF(AND(S6<=260,R6<=50),"特大型","FBA不可")) -> 大型以内 | Y6: 0 | Z6: =M6*'前提条件'!$B$4*(1+'前提条件'!$B$5) -> 4406.4 | AA6: =T6*'前提条件'!$B$6 -> 1294.944 | AB6: =(Z6+AA6)*Y6 -> 0 | AC6: =Z6+N6+AA6+AB6 -> 6201.344 | AD6: =J6/(1+'前提条件'!$B$13) -> 16345.455 | AE6: =J6*E6 -> 2768.92 | AF6: =AD6*'前提条件'!$B$8 -> 1634.5455 | AG6: =AD6*'前提条件'!$B$9 -> 653.81818 | AH6: =T6*'前提条件'!$B$10*'前提条件'!$B$11 -> 485.604 | AI6: ='前提条件'!$B$12 -> 300 | AJ6: =AD6-AE6-W6-AF6-AG6-AH6-AI6-AC6 -> 2851.2229 | AK6: =IF(AD6>0,AJ6/AD6,0) -> 0.17443522 | AL6: =IF(AD6>0,(AJ6+AF6)/AD6,0) -> 0.27443522 | AM6: =IF(AC6>0,AJ6/AC6,0) -> 0.459775 | AN6: 150 | AO6: =J6*AN6 -> 2697000 | AP6: =AJ6*AN6 -> 427683.44 | AQ6: =IF(AJ6>0,ROUNDUP('前提条件'!$B$15/AJ6,0),"赤字") -> 351 | AR6: =W6+(AJ6-'前提条件'!$B$14*AD6) -> 1849.4047 | AS6: =M6+(AJ6-'前提条件'!$B$14*AD6)/('前提条件'!$B$4*(1+'前提条件'!$B$5)*(1+Y6)) -> 185.40913 | AT6: =IF(AK6>='前提条件'!$B$14,"◎ 15%以上",IF(AK6>='前提条件'!$B$16,"△ 条件付き","× 除外")) -> ◎ 15%以上 | AU6: ①支柱Φ12cm以上・ベース70×50cmの重量級で揺れを抑える②転倒防止ベルト・壁固定金具を同梱③交換用麻スリーブ・パーツを単品販売（リピート収益）④クッション・ハンモックは外して洗える⑤各段の耐荷重表示と増し締めガイド⑥梱包を160サイズ内に設計 | AV6: 重く安定し6kgの大型猫2匹が暴れても揺れない製品が高評価／転倒防止帯付き／ベッド・ハンモックが外して洗える／太い爪とぎポールが多い／登りやすいステップ配置 | AW6: 【高】据え置きは揺れる（重りを置く・壁に寄せる等で自衛している）／【高】ネジが緩む→定期的な増し締めが必要／【中】麻がボロボロになるが交換できない／【中】届く箱が非常に重い／【中】ハンモック布の破れ | AX6: 【高】揺れ・転倒対策（極太支柱＋重量ベース＋固定キット） | AY6: 競合・レビュー=B／原価・月販=C（仕入¥185元超または売価¥16,980以下だと15%割れ） | AZ6: 1688で缅因猫向け粗柱モデル3社見積＋耐荷重試験動画の提出依頼／180cm帯上位10品の価格・月販を確認
A7: 3 | B7: ゴルフバッグ2台収納ラック（固定ベルト・洗える泥受け） | C7: 玄関・ガレージでキャディバッグ2本＋シューズ＋小物を一括収納。『倒れない・床が汚れない』で既存品と差別化 | D7: スポーツ&アウトドア | E7: =IFERROR(INDEX('前提条件'!$B$20:$B$28,MATCH(D7,'前提条件'!$A$20:$A$28,0)),'前提条件'!$B$20) -> 0.104 | F7: Bonarca（幅63cm・2バッグ・棚・S字フック・転倒防止）B09TKTDXRQ、Bornran 2本用（キャスター・4段棚・136kg）、VKEID B0CD7MBTD3、MOBAAK B0DG62RPT1 | G7: https://www.amazon.co.jp/dp/B09TKTDXRQ | H7: Bonarca ¥10,900（検索結果の表示価格） | I7: Amazonで検索 | J7: 12980 | K7: 高尔夫球包收纳架 双包 车库 置物架 带轮 | L7: 1688で検索 | M7: 110 | N7: 400 | O7: 85 | P7: 42 | Q7: 15 | R7: 14 | S7: =O7+P7+Q7 -> 142 | T7: =O7*P7*Q7/1000000 -> 0.05355 | U7: =MAX(MATCH(S7,'前提条件'!$C$34:$C$46,1),INDEX('前提条件'!$J$34:$J$41,MATCH(R7,'前提条件'!$H$34:$H$41,1))) -> 6 | V7: =INDEX('前提条件'!$B$34:$B$46,U7) -> 160サイズ | W7: =INDEX('前提条件'!$E$34:$E$46,U7)*'前提条件'!$B$7 -> 1450 | X7: =IF(AND(S7<=200,R7<=40),"大型以内",IF(AND(S7<=260,R7<=50),"特大型","FBA不可")) -> 大型以内 | Y7: 0 | Z7: =M7*'前提条件'!$B$4*(1+'前提条件'!$B$5) -> 2851.2 | AA7: =T7*'前提条件'!$B$6 -> 642.6 | AB7: =(Z7+AA7)*Y7 -> 0 | AC7: =Z7+N7+AA7+AB7 -> 3893.8 | AD7: =J7/(1+'前提条件'!$B$13) -> 11800 | AE7: =J7*E7 -> 1349.92 | AF7: =AD7*'前提条件'!$B$8 -> 1180 | AG7: =AD7*'前提条件'!$B$9 -> 472 | AH7: =T7*'前提条件'!$B$10*'前提条件'!$B$11 -> 240.975 | AI7: ='前提条件'!$B$12 -> 300 | AJ7: =AD7-AE7-W7-AF7-AG7-AH7-AI7-AC7 -> 2913.305 | AK7: =IF(AD7>0,AJ7/AD7,0) -> 0.24689025 | AL7: =IF(AD7>0,(AJ7+AF7)/AD7,0) -> 0.34689025 | AM7: =IF(AC7>0,AJ7/AC7,0) -> 0.74819071 | AN7: 60 | AO7: =J7*AN7 -> 778800 | AP7: =AJ7*AN7 -> 174798.3 | AQ7: =IF(AJ7>0,ROUNDUP('前提条件'!$B$15/AJ7,0),"赤字") -> 344 | AR7: =W7+(AJ7-'前提条件'!$B$14*AD7) -> 2593.305 | AS7: =M7+(AJ7-'前提条件'!$B$14*AD7)/('前提条件'!$B$4*(1+'前提条件'!$B$5)*(1+Y7)) -> 154.10899 | AT7: =IF(AK7>='前提条件'!$B$14,"◎ 15%以上",IF(AK7>='前提条件'!$B$16,"△ 条件付き","× 除外")) -> ◎ 15%以上 | AU7: ①バッグ固定ベルト（転倒防止）②外して洗える泥受けトレー③高さ調整式シューズ棚④ロック付きキャスター⑤ボール・手袋用の小物フック⑥壁固定金具 | AV7: 2本置いてもグラつかない／前後の転倒防止バーがしっかり支える／バッグ・小物までまとめて片付く | AW7: 【中】製品ごとの品質のばらつきを不安視する声／【中】（一般傾向）泥・芝で床が汚れる／【中】キャスターのロック有無／【低】組立説明の分かりにくさ | AX7: 【高】固定ベルト＋洗える泥受け（転倒と床汚れの解消） | AY7: 競合=B（Bonarca価格は検索結果表示）／レビューはB（件数少）／原価・月販=C | AZ7: Bonarca等の星3以下レビューをAmazonで直接精読／春秋の季節変動を確認／1688で车库用双包ラック見積
A8: 4 | B8: 自転車2台スタンド（自立式・室内縦置き） | C8: ロード・クロス・子供車2台を室内に縦置き。天井に依存しない自立式＋フック無段階調整＋小物棚で、国産（¥19,900）の半額帯を狙う | D8: スポーツ&アウトドア | E8: =IFERROR(INDEX('前提条件'!$B$20:$B$28,MATCH(D8,'前提条件'!$A$20:$A$28,0)),'前提条件'!$B$20) -> 0.104 | F8: 足立製作所 2台用 棚付き 2434（¥19,900・日本製）／1530、ぼん家具 2台用、MOJYU Lex、WEIMALL 突っ張り式 | G8: https://store.shopping.yahoo.co.jp/adachiseisakusyo/2434.html | H8: 足立製作所 2434 ¥19,900 送料無料（検索結果） | I8: Amazonで検索 | J8: 9980 | K8: 自行车停车架 室内 立式 双车 挂架 落地 | L8: 1688で検索 | M8: 90 | N8: 300 | O8: 110 | P8: 30 | Q8: 12 | R8: 9 | S8: =O8+P8+Q8 -> 152 | T8: =O8*P8*Q8/1000000 -> 0.0396 | U8: =MAX(MATCH(S8,'前提条件'!$C$34:$C$46,1),INDEX('前提条件'!$J$34:$J$41,MATCH(R8,'前提条件'!$H$34:$H$41,1))) -> 6 | V8: =INDEX('前提条件'!$B$34:$B$46,U8) -> 160サイズ | W8: =INDEX('前提条件'!$E$34:$E$46,U8)*'前提条件'!$B$7 -> 1450 | X8: =IF(AND(S8<=200,R8<=40),"大型以内",IF(AND(S8<=260,R8<=50),"特大型","FBA不可")) -> 大型以内 | Y8: 0 | Z8: =M8*'前提条件'!$B$4*(1+'前提条件'!$B$5) -> 2332.8 | AA8: =T8*'前提条件'!$B$6 -> 475.2 | AB8: =(Z8+AA8)*Y8 -> 0 | AC8: =Z8+N8+AA8+AB8 -> 3108 | AD8: =J8/(1+'前提条件'!$B$13) -> 9072.7273 | AE8: =J8*E8 -> 1037.92 | AF8: =AD8*'前提条件'!$B$8 -> 907.27273 | AG8: =AD8*'前提条件'!$B$9 -> 362.90909 | AH8: =T8*'前提条件'!$B$10*'前提条件'!$B$11 -> 178.2 | AI8: ='前提条件'!$B$12 -> 300 | AJ8: =AD8-AE8-W8-AF8-AG8-AH8-AI8-AC8 -> 1728.4255 | AK8: =IF(AD8>0,AJ8/AD8,0) -> 0.19050782 | AL8: =IF(AD8>0,(AJ8+AF8)/AD8,0) -> 0.29050782 | AM8: =IF(AC8>0,AJ8/AC8,0) -> 0.55612145 | AN8: 100 | AO8: =J8*AN8 -> 998000 | AP8: =AJ8*AN8 -> 172842.55 | AQ8: =IF(AJ8>0,ROUNDUP('前提条件'!$B$15/AJ8,0),"赤字") -> 579 | AR8: =W8+(AJ8-'前提条件'!$B$14*AD8) -> 1817.5164 | AS8: =M8+(AJ8-'前提条件'!$B$14*AD8)/('前提条件'!$B$4*(1+'前提条件'!$B$5)*(1+Y8)) -> 104.17887 | AT8: =IF(AK8>='前提条件'!$B$14,"◎ 15%以上",IF(AK8>='前提条件'!$B$16,"△ 条件付き","× 除外")) -> ◎ 15%以上 | AU8: ①フック高さ・幅・角度を無段階調整②床保護マット＋タイヤ受け③ヘルメット・小物棚④突っ張り不要の自立式（天井高を問わない）⑤1台20kgの耐荷重表示と車種別適合表 | AV8: ロードバイク2台でもぐらつかない／日本製は安っぽいパーツがないと好評／シンプルなデザイン／フックの高さ・角度調整 | AW8: 【高】突っ張り式は天井が高すぎる・弱いと使えない（天井高203〜268cm等の制約）／【中】天井・壁の傷／【中】フック位置が合わない車種 | AX8: 【高】天井に依存しない自立構造＋車種別フック | AY8: 競合=B（足立製作所の価格・仕様は検索結果）／原価・月販=C | AZ8: 1688で重量ベース型の自立式双车架を見積／適合車種表の作成／突っ張り式との比較画像
A9: 5 | B9: A3複合機対応プリンターワゴン（横揺れ防止・大径キャスター） | C9: 20〜30kgのA3インクジェット複合機を載せても印刷中に揺れない業務用ワゴン。国内メーカー品より安く、中国系汎用品より頑丈に | D9: 文房具・オフィス用品 | E9: =IFERROR(INDEX('前提条件'!$B$20:$B$28,MATCH(D9,'前提条件'!$A$20:$A$28,0)),'前提条件'!$B$20) -> 0.154 | F9: PUNCIA 3段（W50×D40×H73・120kg）B0DCMV6DKF、サンワサプライ LPS-T6060L（60×60×50・100kg）、山崎実業、margherita A3 Storage Cart、SS-LPS-01T（80kg） | G9: https://www.amazon.co.jp/dp/B0DCMV6DKF | H9: 価格未確認（中国系3段ワゴンは¥6,000〜10,000程度と推定、サンワ等の国内品は上位価格帯） | I9: Amazonで検索 | J9: 10980 | K9: 打印机推车 A3 复印机架 带轮 三层 钢木 | L9: 1688で検索 | M9: 85 | N9: 300 | O9: 66 | P9: 56 | Q9: 15 | R9: 15 | S9: =O9+P9+Q9 -> 137 | T9: =O9*P9*Q9/1000000 -> 0.05544 | U9: =MAX(MATCH(S9,'前提条件'!$C$34:$C$46,1),INDEX('前提条件'!$J$34:$J$41,MATCH(R9,'前提条件'!$H$34:$H$41,1))) -> 5 | V9: =INDEX('前提条件'!$B$34:$B$46,U9) -> 140サイズ | W9: =INDEX('前提条件'!$E$34:$E$46,U9)*'前提条件'!$B$7 -> 1250 | X9: =IF(AND(S9<=200,R9<=40),"大型以内",IF(AND(S9<=260,R9<=50),"特大型","FBA不可")) -> 大型以内 | Y9: 0 | Z9: =M9*'前提条件'!$B$4*(1+'前提条件'!$B$5) -> 2203.2 | AA9: =T9*'前提条件'!$B$6 -> 665.28 | AB9: =(Z9+AA9)*Y9 -> 0 | AC9: =Z9+N9+AA9+AB9 -> 3168.48 | AD9: =J9/(1+'前提条件'!$B$13) -> 9981.8182 | AE9: =J9*E9 -> 1690.92 | AF9: =AD9*'前提条件'!$B$8 -> 998.18182 | AG9: =AD9*'前提条件'!$B$9 -> 399.27273 | AH9: =T9*'前提条件'!$B$10*'前提条件'!$B$11 -> 249.48 | AI9: ='前提条件'!$B$12 -> 300 | AJ9: =AD9-AE9-W9-AF9-AG9-AH9-AI9-AC9 -> 1925.4836 | AK9: =IF(AD9>0,AJ9/AD9,0) -> 0.19289909 | AL9: =IF(AD9>0,(AJ9+AF9)/AD9,0) -> 0.29289909 | AM9: =IF(AC9>0,AJ9/AC9,0) -> 0.60769948 | AN9: 60 | AO9: =J9*AN9 -> 658800 | AP9: =AJ9*AN9 -> 115529.02 | AQ9: =IF(AJ9>0,ROUNDUP('前提条件'!$B$15/AJ9,0),"赤字") -> 520 | AR9: =W9+(AJ9-'前提条件'!$B$14*AD9) -> 1678.2109 | AS9: =M9+(AJ9-'前提条件'!$B$14*AD9)/('前提条件'!$B$4*(1+'前提条件'!$B$5)*(1+Y9)) -> 101.52048 | AT9: =IF(AK9>='前提条件'!$B$14,"◎ 15%以上",IF(AK9>='前提条件'!$B$16,"△ 条件付き","× 除外")) -> ◎ 15%以上 | AU9: ①背面パネル＋筋交いで印刷中の横揺れを防止②Φ75mm以上の静音キャスター（全輪ストッパー）③A3/A4用紙の仕切り・引き出し④天板耐荷重60kg表示⑤主要A3複合機（EPSON/Brother/Canon）の適合寸法表 | AV9: 組立20分程度で簡単／約25kgの複合機でも強度に問題なし／全キャスターにストッパー／中棚を5cm間隔で調整できる | AW9: 【高】複合機の印刷中に揺れる／【高】天板が直角に留まらない等の部材精度の不良（PUNCIAのレビュー）／【中】耐荷重不足（天板40kg・底板15kg等） | AX9: 【高】横揺れ対策（背面パネル）と部材精度の検品基準 | AY9: 競合=B／価格帯・原価・月販=C（売価¥9,980まで下げると15%割れ） | AZ9: A3複合機の外寸・重量リスト化／1688で背面板付きモデルを見積／サンワ製品の実売価格を確認
A10: 6 | B10: 洗濯機上ランドリーラック（蛇口・防水パン干渉ゼロ設計） | C10: 『蛇口に当たる・防水パンでぐらつく・天井が低い』で置けない不満を解消する上位価格帯モデル | D10: ホーム&キッチン | E10: =IFERROR(INDEX('前提条件'!$B$20:$B$28,MATCH(D10,'前提条件'!$A$20:$A$28,0)),'前提条件'!$B$20) -> 0.154 | F10: 山善 WJL-HS1（幅83-110×奥行52×高さ190-255cm）B07Q51GGGB、アイリスオーヤマ BSSL-860R／HSLR-EX895（全体13kg・棚5kg）、BAOYOUNI 突っ張り | G10: https://www.amazon.co.jp/dp/B07Q51GGGB | H10: 価格未確認（大手品は数千円台と推定→当社は上位価格帯を狙う） | I10: Amazonで検索 | J10: 7980 | K10: 洗衣机置物架 落地 可伸缩 滚筒 卫生间 | L10: 1688で検索 | M10: 55 | N10: 250 | O10: 95 | P10: 22 | Q10: 10 | R10: 7 | S10: =O10+P10+Q10 -> 127 | T10: =O10*P10*Q10/1000000 -> 0.0209 | U10: =MAX(MATCH(S10,'前提条件'!$C$34:$C$46,1),INDEX('前提条件'!$J$34:$J$41,MATCH(R10,'前提条件'!$H$34:$H$41,1))) -> 5 | V10: =INDEX('前提条件'!$B$34:$B$46,U10) -> 140サイズ | W10: =INDEX('前提条件'!$E$34:$E$46,U10)*'前提条件'!$B$7 -> 1250 | X10: =IF(AND(S10<=200,R10<=40),"大型以内",IF(AND(S10<=260,R10<=50),"特大型","FBA不可")) -> 大型以内 | Y10: 0 | Z10: =M10*'前提条件'!$B$4*(1+'前提条件'!$B$5) -> 1425.6 | AA10: =T10*'前提条件'!$B$6 -> 250.8 | AB10: =(Z10+AA10)*Y10 -> 0 | AC10: =Z10+N10+AA10+AB10 -> 1926.4 | AD10: =J10/(1+'前提条件'!$B$13) -> 7254.5455 | AE10: =J10*E10 -> 1228.92 | AF10: =AD10*'前提条件'!$B$8 -> 725.45455 | AG10: =AD10*'前提条件'!$B$9 -> 290.18182 | AH10: =T10*'前提条件'!$B$10*'前提条件'!$B$11 -> 94.05 | AI10: ='前提条件'!$B$12 -> 300 | AJ10: =AD10-AE10-W10-AF10-AG10-AH10-AI10-AC10 -> 1439.5391 | AK10: =IF(AD10>0,AJ10/AD10,0) -> 0.19843271 | AL10: =IF(AD10>0,(AJ10+AF10)/AD10,0) -> 0.29843271 | AM10: =IF(AC10>0,AJ10/AC10,0) -> 0.74726905 | AN10: 200 | AO10: =J10*AN10 -> 1596000 | AP10: =AJ10*AN10 -> 287907.82 | AQ10: =IF(AJ10>0,ROUNDUP('前提条件'!$B$15/AJ10,0),"赤字") -> 695 | AR10: =W10+(AJ10-'前提条件'!$B$14*AD10) -> 1601.3573 | AS10: =M10+(AJ10-'前提条件'!$B$14*AD10)/('前提条件'!$B$4*(1+'前提条件'!$B$5)*(1+Y10)) -> 68.55545 | AT10: =IF(AK10>='前提条件'!$B$14,"◎ 15%以上",IF(AK10>='前提条件'!$B$16,"△ 条件付き","× 除外")) -> ◎ 15%以上 | AU10: ①蛇口位置に合わせて棚をずらせるオフセット棚②防水パンの段差用アジャスター脚③天井高190cm〜対応④棚耐荷重10kg・筋交いで強化⑤購入前チェックシート（蛇口・防水パン・天井高） | AV10: 大型洗濯機に対応／防水パンと床を跨いで設置できる／組立が簡単／筋交い構造でぐらつきにくい | AW10: 【高】蛇口に当たって設置できない・ホースが無理な角度に／【高】脚が防水パンの段差に乗ってぐらつく／【中】突っ張り部が外れやすい／【中】防水パンから天井まで約200cmで合う製品がない／【中】洗濯機の蓋が開かない | AX10: 【高】蛇口・防水パンとの干渉の解消（オフセット棚＋段差アジャスター） | AY10: 競合・レビュー=B／価格帯・原価・月販=C（売価¥6,980だと利益率約13%） | AZ10: 上位10品の実売価格を確認（価格リスク）／1688で可伸缩落地架を見積／耐荷重試験
A11: 7 | B11: ボール収納ワゴン（学校・クラブ向け・キャスター付き） | C11: 部活・スポーツ少年団・体育館向け。耐荷重強化とキャスター強化、交換用バッグの継続販売で業務需要を取る | D11: スポーツ&アウトドア | E11: =IFERROR(INDEX('前提条件'!$B$20:$B$28,MATCH(D11,'前提条件'!$A$20:$A$28,0)),'前提条件'!$B$20) -> 0.104 | F11: Earth Wing ボールカゴ（67×67×88cm・約3kg・耐荷重約7kg・¥8,480）、molten ボールかご、体育館用ボールカート | G11: https://store.shopping.yahoo.co.jp/discount-spirits2/a000000131862-copy.html | H11: Earth Wing ¥8,480（検索結果） | I11: Amazonで検索 | J11: 9980 | K11: 球车 篮球收纳车 带轮 折叠 学校 体育器材 | L11: 1688で検索 | M11: 80 | N11: 300 | O11: 90 | P11: 55 | Q11: 12 | R11: 10 | S11: =O11+P11+Q11 -> 157 | T11: =O11*P11*Q11/1000000 -> 0.0594 | U11: =MAX(MATCH(S11,'前提条件'!$C$34:$C$46,1),INDEX('前提条件'!$J$34:$J$41,MATCH(R11,'前提条件'!$H$34:$H$41,1))) -> 6 | V11: =INDEX('前提条件'!$B$34:$B$46,U11) -> 160サイズ | W11: =INDEX('前提条件'!$E$34:$E$46,U11)*'前提条件'!$B$7 -> 1450 | X11: =IF(AND(S11<=200,R11<=40),"大型以内",IF(AND(S11<=260,R11<=50),"特大型","FBA不可")) -> 大型以内 | Y11: 0 | Z11: =M11*'前提条件'!$B$4*(1+'前提条件'!$B$5) -> 2073.6 | AA11: =T11*'前提条件'!$B$6 -> 712.8 | AB11: =(Z11+AA11)*Y11 -> 0 | AC11: =Z11+N11+AA11+AB11 -> 3086.4 | AD11: =J11/(1+'前提条件'!$B$13) -> 9072.7273 | AE11: =J11*E11 -> 1037.92 | AF11: =AD11*'前提条件'!$B$8 -> 907.27273 | AG11: =AD11*'前提条件'!$B$9 -> 362.90909 | AH11: =T11*'前提条件'!$B$10*'前提条件'!$B$11 -> 267.3 | AI11: ='前提条件'!$B$12 -> 300 | AJ11: =AD11-AE11-W11-AF11-AG11-AH11-AI11-AC11 -> 1660.9255 | AK11: =IF(AD11>0,AJ11/AD11,0) -> 0.18306794 | AL11: =IF(AD11>0,(AJ11+AF11)/AD11,0) -> 0.28306794 | AM11: =IF(AC11>0,AJ11/AC11,0) -> 0.53814329 | AN11: 40 | AO11: =J11*AN11 -> 399200 | AP11: =AJ11*AN11 -> 66437.018 | AQ11: =IF(AJ11>0,ROUNDUP('前提条件'!$B$15/AJ11,0),"赤字") -> 603 | AR11: =W11+(AJ11-'前提条件'!$B$14*AD11) -> 1750.0164 | AS11: =M11+(AJ11-'前提条件'!$B$14*AD11)/('前提条件'!$B$4*(1+'前提条件'!$B$5)*(1+Y11)) -> 91.574705 | AT11: =IF(AK11>='前提条件'!$B$14,"◎ 15%以上",IF(AK11>='前提条件'!$B$16,"△ 条件付き","× 除外")) -> ◎ 15%以上 | AU11: ①Φ75mmキャスター（2輪ロック）②耐荷重15kg以上に強化③交換用ナイロンバッグを単品販売④学校名などの名入れ対応⑤折りたたみ時の固定ベルト | AV11: 折りたたみで軽く持ち運びやすい／バレーボール5号球が約20個入る／キャスターで移動が楽 | AW11: 【高】耐荷重約7kgと低い／【中】段差や引きずりでキャスターが傷む・根元が破損／【中】（一般傾向）袋の破れ | AX11: 【高】耐荷重とキャスターの強化 | AY11: 競合=B（Earth Wing価格・仕様）／レビュー=B（件数少）／原価・月販=C | AZ11: 学校・クラブの購買（公費・請求書払い）動線を確認／Amazonビジネス価格の設定／1688で篮球车を見積
A12: 8 | B12: サロン収納ワゴン（髪が絡まないキャスター・ドライヤーホルダー） | C12: 美容室・ネイル・エステ向け業務用ワゴン。汎用3段ワゴン（¥2〜5千）と差別化できる業務機能で上位価格帯を狙う | D12: ホーム&キッチン | E12: =IFERROR(INDEX('前提条件'!$B$20:$B$28,MATCH(D12,'前提条件'!$A$20:$A$28,0)),'前提条件'!$B$20) -> 0.154 | F12: Amazonの汎用3段引き出しワゴン（¥2,384〜4,980）、bisella・mateli 美容室ワゴン（木製・ステンレス）、ビューティガレージ | G12: https://www.bisella.com/wagon | H12: 汎用3段ワゴン ¥2,384〜4,980（検索結果）／業務用は上位価格帯（価格未確認） | I12: Amazonで検索 | J12: 7980 | K12: 美发推车 理发店 工具车 带抽屉 吹风机架 | L12: 1688で検索 | M12: 60 | N12: 200 | O12: 60 | P12: 40 | Q12: 15 | R12: 7 | S12: =O12+P12+Q12 -> 115 | T12: =O12*P12*Q12/1000000 -> 0.036 | U12: =MAX(MATCH(S12,'前提条件'!$C$34:$C$46,1),INDEX('前提条件'!$J$34:$J$41,MATCH(R12,'前提条件'!$H$34:$H$41,1))) -> 4 | V12: =INDEX('前提条件'!$B$34:$B$46,U12) -> 120サイズ | W12: =INDEX('前提条件'!$E$34:$E$46,U12)*'前提条件'!$B$7 -> 1050 | X12: =IF(AND(S12<=200,R12<=40),"大型以内",IF(AND(S12<=260,R12<=50),"特大型","FBA不可")) -> 大型以内 | Y12: 0 | Z12: =M12*'前提条件'!$B$4*(1+'前提条件'!$B$5) -> 1555.2 | AA12: =T12*'前提条件'!$B$6 -> 432 | AB12: =(Z12+AA12)*Y12 -> 0 | AC12: =Z12+N12+AA12+AB12 -> 2187.2 | AD12: =J12/(1+'前提条件'!$B$13) -> 7254.5455 | AE12: =J12*E12 -> 1228.92 | AF12: =AD12*'前提条件'!$B$8 -> 725.45455 | AG12: =AD12*'前提条件'!$B$9 -> 290.18182 | AH12: =T12*'前提条件'!$B$10*'前提条件'!$B$11 -> 162 | AI12: ='前提条件'!$B$12 -> 300 | AJ12: =AD12-AE12-W12-AF12-AG12-AH12-AI12-AC12 -> 1310.7891 | AK12: =IF(AD12>0,AJ12/AD12,0) -> 0.18068521 | AL12: =IF(AD12>0,(AJ12+AF12)/AD12,0) -> 0.28068521 | AM12: =IF(AC12>0,AJ12/AC12,0) -> 0.59930006 | AN12: 60 | AO12: =J12*AN12 -> 478800 | AP12: =AJ12*AN12 -> 78647.345 | AQ12: =IF(AJ12>0,ROUNDUP('前提条件'!$B$15/AJ12,0),"赤字") -> 763 | AR12: =W12+(AJ12-'前提条件'!$B$14*AD12) -> 1272.6073 | AS12: =M12+(AJ12-'前提条件'!$B$14*AD12)/('前提条件'!$B$4*(1+'前提条件'!$B$5)*(1+Y12)) -> 68.588244 | AT12: =IF(AK12>='前提条件'!$B$14,"◎ 15%以上",IF(AK12>='前提条件'!$B$16,"△ 条件付き","× 除外")) -> ◎ 15%以上 | AU12: ①髪が絡みにくいポールキャスター②耐熱ドライヤー・アイロンホルダー③カラー剤カップホルダー④引き出しストッパー⑤低重心で倒れにくい | AV12: キャスター移動がスムーズ／ドライヤー・カップホルダー付きが好評／収納力 | AW12: 【高】汎用ワゴンとの価格差（¥2〜5千が競合）／【高】キャスターに髪が絡む／【中】（一般傾向）軽くて倒れやすい | AX12: 【高】髪が絡まないキャスター＋業務用の安定性 | AY12: 競合=B／レビュー=B（件数少）／価格帯・原価・月販=C（売価¥6,980だと利益率約11%） | AZ12: 美容ディーラー・ビューティガレージの実売価格を確認（価格リスク）／1688で美发推车を見積
A14: 注記
A15: ・Amazon.co.jp と 1688.com の商品ページは、本作業環境のネットワーク制限で直接開けませんでした。競合の価格・仕様・レビューは検索エンジン経由で確認できた範囲（出典URLは『出典』『レビュー分析』シート）です。
A16: ・1688の仕入単価は市場相場からの推定です。『1688検索リンク』から実際の出品を開き、単価・MOQ・梱包寸法・重量で上書きしてください（黄色セル）。
A17: ・送料は天瞳の送料資料が未共有のため仮置きです。『前提条件』シートの送料表・立米単価を差し替えると、利益・判定・必要月販がすべて再計算されます。
A18: ・『15%達成の国内送料上限』『15%達成の仕入単価上限』は、その金額以下なら利益率15%を満たすという損益分岐の目安です。

Sheet レビュー分析
A1: 関連商品の口コミ分析（高評価・改善要望・優先度）
A2: Amazon・1688の商品ページは本環境から直接閲覧できないため、検索結果の要約・比較記事・販売ページの表記から抽出しました（本文未閲覧を含む）。優先度：高＝製品仕様で必ず解決／中＝できれば仕様で解決／低＝商品ページ・説明書で対応。『要確認』はAmazonレビューの精読が必要な一般傾向です。
A4: 商品 | B4: 区分 | C4: 口コミの要旨 | D4: 優先度 | E4: 当社の対応（付加価値への反映） | F4: 出典URL（検索結果） | G4: 確認方法
A5: 大型宅配ボックス | B5: 高評価 | C5: 大容量で複数の荷物が届いても余裕があり、安心して外出できる | D5: — | E5: 110L・投函口3か所の複数投函を標準に | F5: https://my-best.com/5265 | G5: Web検索の要約（本文未閲覧）
A6: 大型宅配ボックス | B6: 高評価 | C6: 防水仕様で天候を気にせず使える／IP55の防塵・防水 | D6: — | E6: 防水パッキン＋排水穴で同等以上を訴求 | F6: https://my-best.com/24523 | G6: Web検索の要約（本文未閲覧）
A7: 大型宅配ボックス | B7: 高評価 | C7: 組立不要・両開き扉で出し入れが楽 | D7: — | E7: 組立式でも工具不要・10分組立を目標（動画付き） | F7: https://my-best.com/24506 | G7: Web検索の要約（本文未閲覧）
A8: 大型宅配ボックス | B8: 高評価 | C8: 印鑑ホルダー・シリンダープッシュ錠で非対面受取ができる | D8: — | E8: 印鑑ホルダー標準装備 | F8: https://360life.shinyusha.co.jp/articles/-/51199 | G8: Web検索の要約（本文未閲覧）
A9: 大型宅配ボックス | B9: 改善要望 | C9: 軽い本体ごと持ち去られる／アンカーで固定しないと不安 | D9: 高 | E9: アンカーボルト＋ワイヤーの固定キット同梱 | F9: https://www.alsok.co.jp/person/recommend/2020/ | G9: Web検索の要約（本文未閲覧）
A10: 大型宅配ボックス | B10: 改善要望 | C10: 南京錠は破られやすい・ダイヤル番号を推測される | D10: 高 | E10: オートリセット式ダイヤル錠＋予備鍵 | F10: https://www.alsok.co.jp/person/recommend/2020/ | G10: Web検索の要約（本文未閲覧）
A11: 大型宅配ボックス | B11: 改善要望 | C11: 傷から錆びる、鍵部が雨で錆びる・電子錠の故障 | D11: 高 | E11: 厚膜粉体塗装・ステンレス蝶番、機械式錠 | F11: https://www.alsok.co.jp/person/recommend/2020/ | G11: Web検索の要約（本文未閲覧）
A12: 大型宅配ボックス | B12: 改善要望 | C12: 設置スペース・固定工事の手間 | D12: 中 | E12: 設置寸法シートと固定方法の動画 | F12: https://exterior100.lixil.co.jp/articles/37/ | G12: Web検索の要約（本文未閲覧）
A13: 大型猫用キャットタワー | B13: 高評価 | C13: 重くどっしりして、6kgのメインクーン2匹が暴れても安定 | D13: — | E13: 重量ベース（70×50cm）を最大の訴求点に | F13: https://my-best.com/14984 | G13: Web検索の要約（本文未閲覧）
A14: 大型猫用キャットタワー | B14: 高評価 | C14: 転倒防止帯付き、ベッド・ハンモックが外して洗える | D14: — | E14: 固定キット・洗えるカバーを標準装備 | F14: https://my-best.com/14984 | G14: Web検索の要約（本文未閲覧）
A15: 大型猫用キャットタワー | B15: 高評価 | C15: 太い爪とぎポールが多い（直径30/35cmの大型・特大型） | D15: — | E15: 支柱Φ12cm以上 | F15: https://my-best.com/14984 | G15: Web検索の要約（本文未閲覧）
... A52: （参考）業務用リネン回収カート | B52: 改善要望 | C52: （選定ポイント）客室フロアでの走行音、キャスター・バッグの消耗 | D52: 中 | E52: 静音キャスター・交換用バッグの継続販売 | F52: https://hanger-ya.com/products/c/000000200/ | G52: Web検索の要約（本文未閲覧）

Sheet 月利100万・年商5億計画
A1: 月利100万円・年商5億円に向けた試算
A2: 緑字＝リサーチ表の計算結果を参照／青字＝計画値（編集可）。利益は広告・返品・保管・出荷作業控除後、固定費（人件費・サンプル費等）控除前。
A4: ① 月利100万円に必要な月販（利益率15%以上の8商品）
A5: 優先順位 | B5: 商品名 | C5: 販売価格（税込） | D5: 利益（円/個） | E5: 利益率 | F5: 月利100万に必要な月販 | G5: 想定月販（単品・Amazon） | H5: 到達率 | I5: 見立て
A6: ='リサーチ表(15%以上)'!A5 -> 1 | B6: ='リサーチ表(15%以上)'!B5 -> 大型宅配ボックス（戸建て・組立式スチール110L） | C6: ='リサーチ表(15%以上)'!J5 -> 19800 | D6: ='リサーチ表(15%以上)'!AJ5 -> 2764.176 | E6: ='リサーチ表(15%以上)'!AK5 -> 0.15356533 | F6: ='リサーチ表(15%以上)'!AQ5 -> 362 | G6: ='リサーチ表(15%以上)'!AN5 -> 250 | H6: =IF(ISNUMBER(F6),G6/F6,0) -> 0.69060773 | I6: =IF(H6>=1,"単品で到達",IF(H6>=0.4,"サイズ・色展開＋楽天/Yahoo!併売で到達圏","単品では困難（補完商品）")) -> サイズ・色展開＋楽天/Yahoo!併売で到達圏
A7: ='リサーチ表(15%以上)'!A6 -> 2 | B7: ='リサーチ表(15%以上)'!B6 -> 大型猫用キャットタワー（180cm・極太支柱・揺れ対策） | C7: ='リサーチ表(15%以上)'!J6 -> 17980 | D7: ='リサーチ表(15%以上)'!AJ6 -> 2851.2229 | E7: ='リサーチ表(15%以上)'!AK6 -> 0.17443522 | F7: ='リサーチ表(15%以上)'!AQ6 -> 351 | G7: ='リサーチ表(15%以上)'!AN6 -> 150 | H7: =IF(ISNUMBER(F7),G7/F7,0) -> 0.42735043 | I7: =IF(H7>=1,"単品で到達",IF(H7>=0.4,"サイズ・色展開＋楽天/Yahoo!併売で到達圏","単品では困難（補完商品）")) -> サイズ・色展開＋楽天/Yahoo!併売で到達圏
A8: ='リサーチ表(15%以上)'!A7 -> 3 | B8: ='リサーチ表(15%以上)'!B7 -> ゴルフバッグ2台収納ラック（固定ベルト・洗える泥受け） | C8: ='リサーチ表(15%以上)'!J7 -> 12980 | D8: ='リサーチ表(15%以上)'!AJ7 -> 2913.305 | E8: ='リサーチ表(15%以上)'!AK7 -> 0.24689025 | F8: ='リサーチ表(15%以上)'!AQ7 -> 344 | G8: ='リサーチ表(15%以上)'!AN7 -> 60 | H8: =IF(ISNUMBER(F8),G8/F8,0) -> 0.1744186 | I8: =IF(H8>=1,"単品で到達",IF(H8>=0.4,"サイズ・色展開＋楽天/Yahoo!併売で到達圏","単品では困難（補完商品）")) -> 単品では困難（補完商品）
A9: ='リサーチ表(15%以上)'!A8 -> 4 | B9: ='リサーチ表(15%以上)'!B8 -> 自転車2台スタンド（自立式・室内縦置き） | C9: ='リサーチ表(15%以上)'!J8 -> 9980 | D9: ='リサーチ表(15%以上)'!AJ8 -> 1728.4255 | E9: ='リサーチ表(15%以上)'!AK8 -> 0.19050782 | F9: ='リサーチ表(15%以上)'!AQ8 -> 579 | G9: ='リサーチ表(15%以上)'!AN8 -> 100 | H9: =IF(ISNUMBER(F9),G9/F9,0) -> 0.17271157 | I9: =IF(H9>=1,"単品で到達",IF(H9>=0.4,"サイズ・色展開＋楽天/Yahoo!併売で到達圏","単品では困難（補完商品）")) -> 単品では困難（補完商品）
A10: ='リサーチ表(15%以上)'!A9 -> 5 | B10: ='リサーチ表(15%以上)'!B9 -> A3複合機対応プリンターワゴン（横揺れ防止・大径キャスター） | C10: ='リサーチ表(15%以上)'!J9 -> 10980 | D10: ='リサーチ表(15%以上)'!AJ9 -> 1925.4836 | E10: ='リサーチ表(15%以上)'!AK9 -> 0.19289909 | F10: ='リサーチ表(15%以上)'!AQ9 -> 520 | G10: ='リサーチ表(15%以上)'!AN9 -> 60 | H10: =IF(ISNUMBER(F10),G10/F10,0) -> 0.11538462 | I10: =IF(H10>=1,"単品で到達",IF(H10>=0.4,"サイズ・色展開＋楽天/Yahoo!併売で到達圏","単品では困難（補完商品）")) -> 単品では困難（補完商品）
A11: ='リサーチ表(15%以上)'!A10 -> 6 | B11: ='リサーチ表(15%以上)'!B10 -> 洗濯機上ランドリーラック（蛇口・防水パン干渉ゼロ設計） | C11: ='リサーチ表(15%以上)'!J10 -> 7980 | D11: ='リサーチ表(15%以上)'!AJ10 -> 1439.5391 | E11: ='リサーチ表(15%以上)'!AK10 -> 0.19843271 | F11: ='リサーチ表(15%以上)'!AQ10 -> 695 | G11: ='リサーチ表(15%以上)'!AN10 -> 200 | H11: =IF(ISNUMBER(F11),G11/F11,0) -> 0.28776978 | I11: =IF(H11>=1,"単品で到達",IF(H11>=0.4,"サイズ・色展開＋楽天/Yahoo!併売で到達圏","単品では困難（補完商品）")) -> 単品では困難（補完商品）
A12: ='リサーチ表(15%以上)'!A11 -> 7 | B12: ='リサーチ表(15%以上)'!B11 -> ボール収納ワゴン（学校・クラブ向け・キャスター付き） | C12: ='リサーチ表(15%以上)'!J11 -> 9980 | D12: ='リサーチ表(15%以上)'!AJ11 -> 1660.9255 | E12: ='リサーチ表(15%以上)'!AK11 -> 0.18306794 | F12: ='リサーチ表(15%以上)'!AQ11 -> 603 | G12: ='リサーチ表(15%以上)'!AN11 -> 40 | H12: =IF(ISNUMBER(F12),G12/F12,0) -> 0.066334992 | I12: =IF(H12>=1,"単品で到達",IF(H12>=0.4,"サイズ・色展開＋楽天/Yahoo!併売で到達圏","単品では困難（補完商品）")) -> 単品では困難（補完商品）
A13: ='リサーチ表(15%以上)'!A12 -> 8 | B13: ='リサーチ表(15%以上)'!B12 -> サロン収納ワゴン（髪が絡まないキャスター・ドライヤーホルダー） | C13: ='リサーチ表(15%以上)'!J12 -> 7980 | D13: ='リサーチ表(15%以上)'!AJ12 -> 1310.7891 | E13: ='リサーチ表(15%以上)'!AK12 -> 0.18068521 | F13: ='リサーチ表(15%以上)'!AQ12 -> 763 | G13: ='リサーチ表(15%以上)'!AN12 -> 60 | H13: =IF(ISNUMBER(F13),G13/F13,0) -> 0.078636959 | I13: =IF(H13>=1,"単品で到達",IF(H13>=0.4,"サイズ・色展開＋楽天/Yahoo!併売で到達圏","単品では困難（補完商品）")) -> 単品では困難（補完商品）
A16: ② 年商5億円ロードマップ（試算）
A17: 楽天・Yahoo!併売係数 | C17: 1.3 | D17: Amazon月販に対する全モール合計の倍率（仮定）
A18: 目標年商（円） | C18: 500000000
A19: 目標年収（円） | C19: 50000000
A21: 優先順位 | B21: 商品名 | C21: 販売価格（税込） | D21: 利益（円/個） | E21: 展開SKU数 | F21: 1SKUの月販（Amazon） | G21: 月販合計（併売込み） | H21: 月商（税込） | I21: 月利 | J21: 年商 | K21: 年間利益
A22: ='リサーチ表(15%以上)'!A5 -> 1 | B22: ='リサーチ表(15%以上)'!B5 -> 大型宅配ボックス（戸建て・組立式スチール110L） | C22: ='リサーチ表(15%以上)'!J5 -> 19800 | D22: ='リサーチ表(15%以上)'!AJ5 -> 2764.176 | E22: 3 | F22: 150 | G22: =E22*F22*$C$17 -> 585 | H22: =G22*C22 -> 11583000 | I22: =G22*D22 -> 1617043 | J22: =H22*12 -> 138996000 | K22: =I22*12 -> 19404516
A23: ='リサーチ表(15%以上)'!A6 -> 2 | B23: ='リサーチ表(15%以上)'!B6 -> 大型猫用キャットタワー（180cm・極太支柱・揺れ対策） | C23: ='リサーチ表(15%以上)'!J6 -> 17980 | D23: ='リサーチ表(15%以上)'!AJ6 -> 2851.2229 | E23: 2 | F23: 150 | G23: =E23*F23*$C$17 -> 390 | H23: =G23*C23 -> 7012200 | I23: =G23*D23 -> 1111976.9 | J23: =H23*12 -> 84146400 | K23: =I23*12 -> 13343723
A24: ='リサーチ表(15%以上)'!A7 -> 3 | B24: ='リサーチ表(15%以上)'!B7 -> ゴルフバッグ2台収納ラック（固定ベルト・洗える泥受け） | C24: ='リサーチ表(15%以上)'!J7 -> 12980 | D24: ='リサーチ表(15%以上)'!AJ7 -> 2913.305 | E24: 1 | F24: 100 | G24: =E24*F24*$C$17 -> 130 | H24: =G24*C24 -> 1687400 | I24: =G24*D24 -> 378729.65 | J24: =H24*12 -> 20248800 | K24: =I24*12 -> 4544755.8
A25: ='リサーチ表(15%以上)'!A8 -> 4 | B25: ='リサーチ表(15%以上)'!B8 -> 自転車2台スタンド（自立式・室内縦置き） | C25: ='リサーチ表(15%以上)'!J8 -> 9980 | D25: ='リサーチ表(15%以上)'!AJ8 -> 1728.4255 | E25: 2 | F25: 80 | G25: =E25*F25*$C$17 -> 208 | H25: =G25*C25 -> 2075840 | I25: =G25*D25 -> 359512.49 | J25: =H25*12 -> 24910080 | K25: =I25*12 -> 4314149.9
A26: ='リサーチ表(15%以上)'!A9 -> 5 | B26: ='リサーチ表(15%以上)'!B9 -> A3複合機対応プリンターワゴン（横揺れ防止・大径キャスター） | C26: ='リサーチ表(15%以上)'!J9 -> 10980 | D26: ='リサーチ表(15%以上)'!AJ9 -> 1925.4836 | E26: 1 | F26: 100 | G26: =E26*F26*$C$17 -> 130 | H26: =G26*C26 -> 1427400 | I26: =G26*D26 -> 250312.87 | J26: =H26*12 -> 17128800 | K26: =I26*12 -> 3003754.5
A27: ='リサーチ表(15%以上)'!A10 -> 6 | B27: ='リサーチ表(15%以上)'!B10 -> 洗濯機上ランドリーラック（蛇口・防水パン干渉ゼロ設計） | C27: ='リサーチ表(15%以上)'!J10 -> 7980 | D27: ='リサーチ表(15%以上)'!AJ10 -> 1439.5391 | E27: 2 | F27: 120 | G27: =E27*F27*$C$17 -> 312 | H27: =G27*C27 -> 2489760 | I27: =G27*D27 -> 449136.2 | J27: =H27*12 -> 29877120 | K27: =I27*12 -> 5389634.4
A28: ='リサーチ表(15%以上)'!A11 -> 7 | B28: ='リサーチ表(15%以上)'!B11 -> ボール収納ワゴン（学校・クラブ向け・キャスター付き） | C28: ='リサーチ表(15%以上)'!J11 -> 9980 | D28: ='リサーチ表(15%以上)'!AJ11 -> 1660.9255 | E28: 1 | F28: 50 | G28: =E28*F28*$C$17 -> 65 | H28: =G28*C28 -> 648700 | I28: =G28*D28 -> 107960.15 | J28: =H28*12 -> 7784400 | K28: =I28*12 -> 1295521.9
A29: ='リサーチ表(15%以上)'!A12 -> 8 | B29: ='リサーチ表(15%以上)'!B12 -> サロン収納ワゴン（髪が絡まないキャスター・ドライヤーホルダー） | C29: ='リサーチ表(15%以上)'!J12 -> 7980 | D29: ='リサーチ表(15%以上)'!AJ12 -> 1310.7891 | E29: 1 | F29: 80 | G29: =E29*F29*$C$17 -> 104 | H29: =G29*C29 -> 829920 | I29: =G29*D29 -> 136322.07 | J29: =H29*12 -> 9959040 | K29: =I29*12 -> 1635864.8
B30: 合計 | G30: =SUM(G22:G29) -> 1924 | H30: =SUM(H22:H29) -> 27754220 | I30: =SUM(I22:I29) -> 4410993.3 | J30: =SUM(J22:J29) -> 333050640 | K30: =SUM(K22:K29) -> 52931920
B31: 目標年商との差（不足分） | J31: =C18-J30 -> 166949360
B32: 不足分を月商に換算 | H32: =MAX(0,J31)/12 -> 13912447
B33: 年間利益 − 目標年収（固定費控除前） | K33: =K30-C19 -> 2931919.9
A35: ・8商品＋サイズ/色展開＋併売だけでは年商5億に届かない見込み。不足分は『全40候補』の△条件付き商品（猫トイレ収納・ステンレスワゴン・屋外ごみ保管ボックス等）を天瞳の送料で再試算し、15%を満たしたものから追加する。
A36: ・月利100万円に最も近いのは大型宅配ボックスと大型猫用キャットタワー（1個あたり利益が大きく、カテゴリの需要も大きい）。単品で100万円を狙うより、2〜3サイズ展開と楽天・Yahoo!併売で到達させる設計が現実的。
A37: ・想定月販はKeepa／セラースプライトでの実測前の仮置き（データ確度C）。発注前に上位3品の月販を確認し、黄色セルを更新すること。

Sheet 全40候補スクリーニング
A1: 全40候補スクリーニング（前回リストの40商品を同一条件で試算）
A2: 緑字＝『リサーチ表(15%以上)』の入力を参照（厳選8商品はリサーチ表側で編集）。判定：◎＝利益率15%以上／△＝10〜15%（送料・原価しだいで到達）／×＝10%未満。並び順は既定の前提条件での利益率順です。
A3: 候補・売価 | J3: 仕入・梱包・物流 | V3: 損益（1個・税抜） | AA3: 月間 | AD3: 感応度・判定 | AG3: コメント・リンク
A4: 順位（利益率順） | B4: 元リストNo | C4: 区分 | D4: 商品名 | E4: Amazonカテゴリ | F4: 販売手数料率 | G4: 想定販売価格（税込・円） | H4: 価格の根拠（競合価格） | I4: 前回案の目標売価（参考） | J4: 想定仕入単価（元）※推定 | K4: 付加価値コスト（円） | L4: 縦(cm) | M4: 横(cm) | N4: 高さ(cm) | O4: 重量(kg) | P4: 3辺合計 | Q4: 容積(m³) | R4: 区分No | S4: 国内配送サイズ | T4: 国内送料（円） | U4: 関税率 | V4: 着地原価（円） | W4: 税抜売上（円） | X4: 利益（円/個） | Y4: 利益率（税抜売上比） | Z4: 広告前利益率 | AA4: 想定月販（個）※推定 | AB4: 月利（円） | AC4: 月利100万に必要な月販 | AD4: 15%達成の国内送料上限（円） | AE4: 15%達成の仕入単価上限（元） | AF4: 判定 | AG4: 判定理由・コメント | AH4: 競合・参考URL | AI4: 1688検索リンク | AJ4: Amazon検索リンク
A5: 1 | B5: 2 | C5: 上位10 | D5: ='リサーチ表(15%以上)'!B7 -> ゴルフバッグ2台収納ラック（固定ベルト・洗える泥受け） | E5: ='リサーチ表(15%以上)'!D7 -> スポーツ&アウトドア | F5: =IFERROR(INDEX('前提条件'!$B$20:$B$28,MATCH(E5,'前提条件'!$A$20:$A$28,0)),'前提条件'!$B$20) -> 0.104 | G5: ='リサーチ表(15%以上)'!J7 -> 12980 | H5: ='リサーチ表(15%以上)'!H7 -> Bonarca ¥10,900（検索結果の表示価格） | I5: 15980 | J5: ='リサーチ表(15%以上)'!M7 -> 110 | K5: ='リサーチ表(15%以上)'!N7 -> 400 | L5: ='リサーチ表(15%以上)'!O7 -> 85 | M5: ='リサーチ表(15%以上)'!P7 -> 42 | N5: ='リサーチ表(15%以上)'!Q7 -> 15 | O5: ='リサーチ表(15%以上)'!R7 -> 14 | P5: =L5+M5+N5 -> 142 | Q5: =L5*M5*N5/1000000 -> 0.05355 | R5: =MAX(MATCH(P5,'前提条件'!$C$34:$C$46,1),INDEX('前提条件'!$J$34:$J$41,MATCH(O5,'前提条件'!$H$34:$H$41,1))) -> 6 | S5: =INDEX('前提条件'!$B$34:$B$46,R5) -> 160サイズ | T5: =INDEX('前提条件'!$E$34:$E$46,R5)*'前提条件'!$B$7 -> 1450 | U5: ='リサーチ表(15%以上)'!Y7 -> 0 | V5: =J5*'前提条件'!$B$4*(1+'前提条件'!$B$5)+K5+Q5*'前提条件'!$B$6+(J5*'前提条件'!$B$4*(1+'前提条件'!$B$5)+Q5*'前提条件'!$B$6)*U5 -> 3893.8 | W5: =G5/(1+'前提条件'!$B$13) -> 11800 | X5: =W5*(1-'前提条件'!$B$8-'前提条件'!$B$9)-G5*F5-T5-Q5*'前提条件'!$B$10*'前提条件'!$B$11-'前提条件'!$B$12-V5 -> 2913.305 | Y5: =IF(W5>0,X5/W5,0) -> 0.24689025 | Z5: =IF(W5>0,(X5+W5*'前提条件'!$B$8)/W5,0) -> 0.34689025 | AA5: ='リサーチ表(15%以上)'!AN7 -> 60 | AB5: =X5*AA5 -> 174798.3 | AC5: =IF(X5>0,ROUNDUP('前提条件'!$B$15/X5,0),"赤字") -> 344 | AD5: =T5+(X5-'前提条件'!$B$14*W5) -> 2593.305 | AE5: =J5+(X5-'前提条件'!$B$14*W5)/('前提条件'!$B$4*(1+'前提条件'!$B$5)*(1+U5)) -> 154.10899 | AF5: =IF(Y5>='前提条件'!$B$14,"◎ 15%以上",IF(Y5>='前提条件'!$B$16,"△ 条件付き","× 除外")) -> ◎ 15%以上 | AG5: リサーチ表に掲載（優先順位3）。玄関・ガレージでキャディバッグ2本＋シューズ＋小物を一括収納。『倒れない・床が汚れない』で既存品と差別化 | AH5: https://www.amazon.co.jp/dp/B09TKTDXRQ | AI5: 1688で検索 | AJ5: Amazonで検索
A6: 2 | B6: 9 | C6: 上位10 | D6: ='リサーチ表(15%以上)'!B10 -> 洗濯機上ランドリーラック（蛇口・防水パン干渉ゼロ設計） | E6: ='リサーチ表(15%以上)'!D10 -> ホーム&キッチン | F6: =IFERROR(INDEX('前提条件'!$B$20:$B$28,MATCH(E6,'前提条件'!$A$20:$A$28,0)),'前提条件'!$B$20) -> 0.154 | G6: ='リサーチ表(15%以上)'!J10 -> 7980 | H6: ='リサーチ表(15%以上)'!H10 -> 価格未確認（大手品は数千円台と推定→当社は上位価格帯を狙う） | I6: 14980 | J6: ='リサーチ表(15%以上)'!M10 -> 55 | K6: ='リサーチ表(15%以上)'!N10 -> 250 | L6: ='リサーチ表(15%以上)'!O10 -> 95 | M6: ='リサーチ表(15%以上)'!P10 -> 22 | N6: ='リサーチ表(15%以上)'!Q10 -> 10 | O6: ='リサーチ表(15%以上)'!R10 -> 7 | P6: =L6+M6+N6 -> 127 | Q6: =L6*M6*N6/1000000 -> 0.0209 | R6: =MAX(MATCH(P6,'前提条件'!$C$34:$C$46,1),INDEX('前提条件'!$J$34:$J$41,MATCH(O6,'前提条件'!$H$34:$H$41,1))) -> 5 | S6: =INDEX('前提条件'!$B$34:$B$46,R6) -> 140サイズ | T6: =INDEX('前提条件'!$E$34:$E$46,R6)*'前提条件'!$B$7 -> 1250 | U6: ='リサーチ表(15%以上)'!Y10 -> 0 | V6: =J6*'前提条件'!$B$4*(1+'前提条件'!$B$5)+K6+Q6*'前提条件'!$B$6+(J6*'前提条件'!$B$4*(1+'前提条件'!$B$5)+Q6*'前提条件'!$B$6)*U6 -> 1926.4 | W6: =G6/(1+'前提条件'!$B$13) -> 7254.5455 | X6: =W6*(1-'前提条件'!$B$8-'前提条件'!$B$9)-G6*F6-T6-Q6*'前提条件'!$B$10*'前提条件'!$B$11-'前提条件'!$B$12-V6 -> 1439.5391 | Y6: =IF(W6>0,X6/W6,0) -> 0.19843271 | Z6: =IF(W6>0,(X6+W6*'前提条件'!$B$8)/W6,0) -> 0.29843271 | AA6: ='リサーチ表(15%以上)'!AN10 -> 200 | AB6: =X6*AA6 -> 287907.82 | AC6: =IF(X6>0,ROUNDUP('前提条件'!$B$15/X6,0),"赤字") -> 695 | AD6: =T6+(X6-'前提条件'!$B$14*W6) -> 1601.3573 | AE6: =J6+(X6-'前提条件'!$B$14*W6)/('前提条件'!$B$4*(1+'前提条件'!$B$5)*(1+U6)) -> 68.55545 | AF6: =IF(Y6>='前提条件'!$B$14,"◎ 15%以上",IF(Y6>='前提条件'!$B$16,"△ 条件付き","× 除外")) -> ◎ 15%以上 | AG6: リサーチ表に掲載（優先順位6）。『蛇口に当たる・防水パンでぐらつく・天井が低い』で置けない不満を解消する上位価格帯モデル | AH6: https://www.amazon.co.jp/dp/B07Q51GGGB | AI6: 1688で検索 | AJ6: Amazonで検索
A7: 3 | B7: 1 | C7: 上位10 | D7: ='リサーチ表(15%以上)'!B9 -> A3複合機対応プリンターワゴン（横揺れ防止・大径キャスター） | E7: ='リサーチ表(15%以上)'!D9 -> 文房具・オフィス用品 | F7: =IFERROR(INDEX('前提条件'!$B$20:$B$28,MATCH(E7,'前提条件'!$A$20:$A$28,0)),'前提条件'!$B$20) -> 0.154 | G7: ='リサーチ表(15%以上)'!J9 -> 10980 | H7: ='リサーチ表(15%以上)'!H9 -> 価格未確認（中国系3段ワゴンは¥6,000〜10,000程度と推定、サンワ等の国内品は上位価格帯） | I7: 14980 | J7: ='リサーチ表(15%以上)'!M9 -> 85 | K7: ='リサーチ表(15%以上)'!N9 -> 300 | L7: ='リサーチ表(15%以上)'!O9 -> 66 | M7: ='リサーチ表(15%以上)'!P9 -> 56 | N7: ='リサーチ表(15%以上)'!Q9 -> 15 | O7: ='リサーチ表(15%以上)'!R9 -> 15 | P7: =L7+M7+N7 -> 137 | Q7: =L7*M7*N7/1000000 -> 0.05544 | R7: =MAX(MATCH(P7,'前提条件'!$C$34:$C$46,1),INDEX('前提条件'!$J$34:$J$41,MATCH(O7,'前提条件'!$H$34:$H$41,1))) -> 5 | S7: =INDEX('前提条件'!$B$34:$B$46,R7) -> 140サイズ | T7: =INDEX('前提条件'!$E$34:$E$46,R7)*'前提条件'!$B$7 -> 1250 | U7: ='リサーチ表(15%以上)'!Y9 -> 0 | V7: =J7*'前提条件'!$B$4*(1+'前提条件'!$B$5)+K7+Q7*'前提条件'!$B$6+(J7*'前提条件'!$B$4*(1+'前提条件'!$B$5)+Q7*'前提条件'!$B$6)*U7 -> 3168.48 | W7: =G7/(1+'前提条件'!$B$13) -> 9981.8182 | X7: =W7*(1-'前提条件'!$B$8-'前提条件'!$B$9)-G7*F7-T7-Q7*'前提条件'!$B$10*'前提条件'!$B$11-'前提条件'!$B$12-V7 -> 1925.4836 | Y7: =IF(W7>0,X7/W7,0) -> 0.19289909 | Z7: =IF(W7>0,(X7+W7*'前提条件'!$B$8)/W7,0) -> 0.29289909 | AA7: ='リサーチ表(15%以上)'!AN9 -> 60 | AB7: =X7*AA7 -> 115529.02 | AC7: =IF(X7>0,ROUNDUP('前提条件'!$B$15/X7,0),"赤字") -> 520 | AD7: =T7+(X7-'前提条件'!$B$14*W7) -> 1678.2109 | AE7: =J7+(X7-'前提条件'!$B$14*W7)/('前提条件'!$B$4*(1+'前提条件'!$B$5)*(1+U7)) -> 101.52048 | AF7: =IF(Y7>='前提条件'!$B$14,"◎ 15%以上",IF(Y7>='前提条件'!$B$16,"△ 条件付き","× 除外")) -> ◎ 15%以上 | AG7: リサーチ表に掲載（優先順位5）。20〜30kgのA3インクジェット複合機を載せても印刷中に揺れない業務用ワゴン。国内メーカー品より安く、中国系汎用品より頑丈に | AH7: https://www.amazon.co.jp/dp/B0DCMV6DKF | AI7: 1688で検索 | AJ7: Amazonで検索
A8: 4 | B8: 26 | C8: 追加30 | D8: ='リサーチ表(15%以上)'!B8 -> 自転車2台スタンド（自立式・室内縦置き） | E8: ='リサーチ表(15%以上)'!D8 -> スポーツ&アウトドア | F8: =IFERROR(INDEX('前提条件'!$B$20:$B$28,MATCH(E8,'前提条件'!$A$20:$A$28,0)),'前提条件'!$B$20) -> 0.104 | G8: ='リサーチ表(15%以上)'!J8 -> 9980 | H8: ='リサーチ表(15%以上)'!H8 -> 足立製作所 2434 ¥19,900 送料無料（検索結果） | J8: ='リサーチ表(15%以上)'!M8 -> 90 | K8: ='リサーチ表(15%以上)'!N8 -> 300 | L8: ='リサーチ表(15%以上)'!O8 -> 110 | M8: ='リサーチ表(15%以上)'!P8 -> 30 | N8: ='リサーチ表(15%以上)'!Q8 -> 12 | O8: ='リサーチ表(15%以上)'!R8 -> 9 | P8: =L8+M8+N8 -> 152 | Q8: =L8*M8*N8/1000000 -> 0.0396 | R8: =MAX(MATCH(P8,'前提条件'!$C$34:$C$46,1),INDEX('前提条件'!$J$34:$J$41,MATCH(O8,'前提条件'!$H$34:$H$41,1))) -> 6 | S8: =INDEX('前提条件'!$B$34:$B$46,R8) -> 160サイズ | T8: =INDEX('前提条件'!$E$34:$E$46,R8)*'前提条件'!$B$7 -> 1450 | U8: ='リサーチ表(15%以上)'!Y8 -> 0 | V8: =J8*'前提条件'!$B$4*(1+'前提条件'!$B$5)+K8+Q8*'前提条件'!$B$6+(J8*'前提条件'!$B$4*(1+'前提条件'!$B$5)+Q8*'前提条件'!$B$6)*U8 -> 3108 | W8: =G8/(1+'前提条件'!$B$13) -> 9072.7273 | X8: =W8*(1-'前提条件'!$B$8-'前提条件'!$B$9)-G8*F8-T8-Q8*'前提条件'!$B$10*'前提条件'!$B$11-'前提条件'!$B$12-V8 -> 1728.4255 | Y8: =IF(W8>0,X8/W8,0) -> 0.19050782 | Z8: =IF(W8>0,(X8+W8*'前提条件'!$B$8)/W8,0) -> 0.29050782 | AA8: ='リサーチ表(15%以上)'!AN8 -> 100 | AB8: =X8*AA8 -> 172842.55 | AC8: =IF(X8>0,ROUNDUP('前提条件'!$B$15/X8,0),"赤字") -> 579 | AD8: =T8+(X8-'前提条件'!$B$14*W8) -> 1817.5164 | AE8: =J8+(X8-'前提条件'!$B$14*W8)/('前提条件'!$B$4*(1+'前提条件'!$B$5)*(1+U8)) -> 104.17887 | AF8: =IF(Y8>='前提条件'!$B$14,"◎ 15%以上",IF(Y8>='前提条件'!$B$16,"△ 条件付き","× 除外")) -> ◎ 15%以上 | AG8: リサーチ表に掲載（優先順位4）。ロード・クロス・子供車2台を室内に縦置き。天井に依存しない自立式＋フック無段階調整＋小物棚で、国産（¥19,900）の半額帯を狙う | AH8: https://store.shopping.yahoo.co.jp/adachiseisakusyo/2434.html | AI8: 1688で検索 | AJ8: Amazonで検索
A9: 5 | B9: 29 | C9: 追加30 | D9: ='リサーチ表(15%以上)'!B11 -> ボール収納ワゴン（学校・クラブ向け・キャスター付き） | E9: ='リサーチ表(15%以上)'!D11 -> スポーツ&アウトドア | F9: =IFERROR(INDEX('前提条件'!$B$20:$B$28,MATCH(E9,'前提条件'!$A$20:$A$28,0)),'前提条件'!$B$20) -> 0.104 | G9: ='リサーチ表(15%以上)'!J11 -> 9980 | H9: ='リサーチ表(15%以上)'!H11 -> Earth Wing ¥8,480（検索結果） | J9: ='リサーチ表(15%以上)'!M11 -> 80 | K9: ='リサーチ表(15%以上)'!N11 -> 300 | L9: ='リサーチ表(15%以上)'!O11 -> 90 | M9: ='リサーチ表(15%以上)'!P11 -> 55 | N9: ='リサーチ表(15%以上)'!Q11 -> 12 | O9: ='リサーチ表(15%以上)'!R11 -> 10 | P9: =L9+M9+N9 -> 157 | Q9: =L9*M9*N9/1000000 -> 0.0594 | R9: =MAX(MATCH(P9,'前提条件'!$C$34:$C$46,1),INDEX('前提条件'!$J$34:$J$41,MATCH(O9,'前提条件'!$H$34:$H$41,1))) -> 6 | S9: =INDEX('前提条件'!$B$34:$B$46,R9) -> 160サイズ | T9: =INDEX('前提条件'!$E$34:$E$46,R9)*'前提条件'!$B$7 -> 1450 | U9: ='リサーチ表(15%以上)'!Y11 -> 0 | V9: =J9*'前提条件'!$B$4*(1+'前提条件'!$B$5)+K9+Q9*'前提条件'!$B$6+(J9*'前提条件'!$B$4*(1+'前提条件'!$B$5)+Q9*'前提条件'!$B$6)*U9 -> 3086.4 | W9: =G9/(1+'前提条件'!$B$13) -> 9072.7273 | X9: =W9*(1-'前提条件'!$B$8-'前提条件'!$B$9)-G9*F9-T9-Q9*'前提条件'!$B$10*'前提条件'!$B$11-'前提条件'!$B$12-V9 -> 1660.9255 | Y9: =IF(W9>0,X9/W9,0) -> 0.18306794 | Z9: =IF(W9>0,(X9+W9*'前提条件'!$B$8)/W9,0) -> 0.28306794 | AA9: ='リサーチ表(15%以上)'!AN11 -> 40 | AB9: =X9*AA9 -> 66437.018 | AC9: =IF(X9>0,ROUNDUP('前提条件'!$B$15/X9,0),"赤字") -> 603 | AD9: =T9+(X9-'前提条件'!$B$14*W9) -> 1750.0164 | AE9: =J9+(X9-'前提条件'!$B$14*W9)/('前提条件'!$B$4*(1+'前提条件'!$B$5)*(1+U9)) -> 91.574705 | AF9: =IF(Y9>='前提条件'!$B$14,"◎ 15%以上",IF(Y9>='前提条件'!$B$16,"△ 条件付き","× 除外")) -> ◎ 15%以上 | AG9: リサーチ表に掲載（優先順位7）。部活・スポーツ少年団・体育館向け。耐荷重強化とキャスター強化、交換用バッグの継続販売で業務需要を取る | AH9: https://store.shopping.yahoo.co.jp/discount-spirits2/a000000131862-copy.html | AI9: 1688で検索 | AJ9: Amazonで検索
A10: 6 | B10: 38 | C10: 追加30 | D10: ='リサーチ表(15%以上)'!B12 -> サロン収納ワゴン（髪が絡まないキャスター・ドライヤーホルダー） | E10: ='リサーチ表(15%以上)'!D12 -> ホーム&キッチン | F10: =IFERROR(INDEX('前提条件'!$B$20:$B$28,MATCH(E10,'前提条件'!$A$20:$A$28,0)),'前提条件'!$B$20) -> 0.154 | G10: ='リサーチ表(15%以上)'!J12 -> 7980 | H10: ='リサーチ表(15%以上)'!H12 -> 汎用3段ワゴン ¥2,384〜4,980（検索結果）／業務用は上位価格帯（価格未確認） | J10: ='リサーチ表(15%以上)'!M12 -> 60 | K10: ='リサーチ表(15%以上)'!N12 -> 200 | L10: ='リサーチ表(15%以上)'!O12 -> 60 | M10: ='リサーチ表(15%以上)'!P12 -> 40 | N10: ='リサーチ表(15%以上)'!Q12 -> 15 | O10: ='リサーチ表(15%以上)'!R12 -> 7 | P10: =L10+M10+N10 -> 115 | Q10: =L10*M10*N10/1000000 -> 0.036 | R10: =MAX(MATCH(P10,'前提条件'!$C$34:$C$46,1),INDEX('前提条件'!$J$34:$J$41,MATCH(O10,'前提条件'!$H$34:$H$41,1))) -> 4 | S10: =INDEX('前提条件'!$B$34:$B$46,R10) -> 120サイズ | T10: =INDEX('前提条件'!$E$34:$E$46,R10)*'前提条件'!$B$7 -> 1050 | U10: ='リサーチ表(15%以上)'!Y12 -> 0 | V10: =J10*'前提条件'!$B$4*(1+'前提条件'!$B$5)+K10+Q10*'前提条件'!$B$6+(J10*'前提条件'!$B$4*(1+'前提条件'!$B$5)+Q10*'前提条件'!$B$6)*U10 -> 2187.2 | W10: =G10/(1+'前提条件'!$B$13) -> 7254.5455 | X10: =W10*(1-'前提条件'!$B$8-'前提条件'!$B$9)-G10*F10-T10-Q10*'前提条件'!$B$10*'前提条件'!$B$11-'前提条件'!$B$12-V10 -> 1310.7891 | Y10: =IF(W10>0,X10/W10,0) -> 0.18068521 | Z10: =IF(W10>0,(X10+W10*'前提条件'!$B$8)/W10,0) -> 0.28068521 | AA10: ='リサーチ表(15%以上)'!AN12 -> 60 | AB10: =X10*AA10 -> 78647.345 | AC10: =IF(X10>0,ROUNDUP('前提条件'!$B$15/X10,0),"赤字") -> 763 | AD10: =T10+(X10-'前提条件'!$B$14*W10) -> 1272.6073 | AE10: =J10+(X10-'前提条件'!$B$14*W10)/('前提条件'!$B$4*(1+'前提条件'!$B$5)*(1+U10)) -> 68.588244 | AF10: =IF(Y10>='前提条件'!$B$14,"◎ 15%以上",IF(Y10>='前提条件'!$B$16,"△ 条件付き","× 除外")) -> ◎ 15%以上 | AG10: リサーチ表に掲載（優先順位8）。美容室・ネイル・エステ向け業務用ワゴン。汎用3段ワゴン（¥2〜5千）と差別化できる業務機能で上位価格帯を狙う | AH10: https://www.bisella.com/wagon | AI10: 1688で検索 | AJ10: Amazonで検索
A11: 7 | B11: 24 | C11: 追加30 | D11: ='リサーチ表(15%以上)'!B6 -> 大型猫用キャットタワー（180cm・極太支柱・揺れ対策） | E11: ='リサーチ表(15%以上)'!D6 -> ペット用品 | F11: =IFERROR(INDEX('前提条件'!$B$20:$B$28,MATCH(E11,'前提条件'!$A$20:$A$28,0)),'前提条件'!$B$20) -> 0.154 | G11: ='リサーチ表(15%以上)'!J6 -> 17980 | H11: ='リサーチ表(15%以上)'!H6 -> 180cm帯は¥11,980前後の例（楽天検索結果）。大型猫向け上位品の価格は未確認 | J11: ='リサーチ表(15%以上)'!M6 -> 170 | K11: ='リサーチ表(15%以上)'!N6 -> 500 | L11: ='リサーチ表(15%以上)'!O6 -> 82 | M11: ='リサーチ表(15%以上)'!P6 -> 47 | N11: ='リサーチ表(15%以上)'!Q6 -> 28 | O11: ='リサーチ表(15%以上)'!R6 -> 24 | P11: =L11+M11+N11 -> 157 | Q11: =L11*M11*N11/1000000 -> 0.107912 | R11: =MAX(MATCH(P11,'前提条件'!$C$34:$C$46,1),INDEX('前提条件'!$J$34:$J$41,MATCH(O11,'前提条件'!$H$34:$H$41,1))) -> 6 | S11: =INDEX('前提条件'!$B$34:$B$46,R11) -> 160サイズ | T11: =INDEX('前提条件'!$E$34:$E$46,R11)*'前提条件'!$B$7 -> 1450 | U11: ='リサーチ表(15%以上)'!Y6 -> 0 | V11: =J11*'前提条件'!$B$4*(1+'前提条件'!$B$5)+K11+Q11*'前提条件'!$B$6+(J11*'前提条件'!$B$4*(1+'前提条件'!$B$5)+Q11*'前提条件'!$B$6)*U11 -> 6201.344 | W11: =G11/(1+'前提条件'!$B$13) -> 16345.455 | X11: =W11*(1-'前提条件'!$B$8-'前提条件'!$B$9)-G11*F11-T11-Q11*'前提条件'!$B$10*'前提条件'!$B$11-'前提条件'!$B$12-V11 -> 2851.2229 | Y11: =IF(W11>0,X11/W11,0) -> 0.17443522 | Z11: =IF(W11>0,(X11+W11*'前提条件'!$B$8)/W11,0) -> 0.27443522 | AA11: ='リサーチ表(15%以上)'!AN6 -> 150 | AB11: =X11*AA11 -> 427683.44 | AC11: =IF(X11>0,ROUNDUP('前提条件'!$B$15/X11,0),"赤字") -> 351 | AD11: =T11+(X11-'前提条件'!$B$14*W11) -> 1849.4047 | AE11: =J11+(X11-'前提条件'!$B$14*W11)/('前提条件'!$B$4*(1+'前提条件'!$B$5)*(1+U11)) -> 185.40913 | AF11: =IF(Y11>='前提条件'!$B$14,"◎ 15%以上",IF(Y11>='前提条件'!$B$16,"△ 条件付き","× 除外")) -> ◎ 15%以上 | AG11: リサーチ表に掲載（優先順位2）。メインクーン等6kg超の大型猫・多頭飼い特化。極太支柱×重量ベース×転倒防止キットで「揺れない」を訴求し、単価¥17,980帯を狙う | AH11: https://sakura-checker.jp/search/B099RYLG3S/ | AI11: 1688で検索 | AJ11: Amazonで検索
A12: 8 | B12: 32 | C12: 追加30 | D12: ='リサーチ表(15%以上)'!B5 -> 大型宅配ボックス（戸建て・組立式スチール110L） | E12: ='リサーチ表(15%以上)'!D5 -> DIY・工具・ガーデン | F12: =IFERROR(INDEX('前提条件'!$B$20:$B$28,MATCH(E12,'前提条件'!$A$20:$A$28,0)),'前提条件'!$B$20) -> 0.154 | G12: ='リサーチ表(15%以上)'!J5 -> 19800 | H12: ='リサーチ表(15%以上)'!H5 -> タンスのゲン 134L 旧モデル ¥17,999（Yahoo!商品名の表記）／COVELL 140L は価格未確認 | J12: ='リサーチ表(15%以上)'!M5 -> 200 | K12: ='リサーチ表(15%以上)'!N5 -> 500 | L12: ='リサーチ表(15%以上)'!O5 -> 108 | M12: ='リサーチ表(15%以上)'!P5 -> 52 | N12: ='リサーチ表(15%以上)'!Q5 -> 16 | O12: ='リサーチ表(15%以上)'!R5 -> 20 | P12: =L12+M12+N12 -> 176 | Q12: =L12*M12*N12/1000000 -> 0.089856 | R12: =MAX(MATCH(P12,'前提条件'!$C$34:$C$46,1),INDEX('前提条件'!$J$34:$J$41,MATCH(O12,'前提条件'!$H$34:$H$41,1))) -> 8 | S12: =INDEX('前提条件'!$B$34:$B$46,R12) -> 180サイズ | T12: =INDEX('前提条件'!$E$34:$E$46,R12)*'前提条件'!$B$7 -> 2200 | U12: ='リサーチ表(15%以上)'!Y5 -> 0 | V12: =J12*'前提条件'!$B$4*(1+'前提条件'!$B$5)+K12+Q12*'前提条件'!$B$6+(J12*'前提条件'!$B$4*(1+'前提条件'!$B$5)+Q12*'前提条件'!$B$6)*U12 -> 6762.272 | W12: =G12/(1+'前提条件'!$B$13) -> 18000 | X12: =W12*(1-'前提条件'!$B$8-'前提条件'!$B$9)-G12*F12-T12-Q12*'前提条件'!$B$10*'前提条件'!$B$11-'前提条件'!$B$12-V12 -> 2764.176 | Y12: =IF(W12>0,X12/W12,0) -> 0.15356533 | Z12: =IF(W12>0,(X12+W12*'前提条件'!$B$8)/W12,0) -> 0.25356533 | AA12: ='リサーチ表(15%以上)'!AN5 -> 250 | AB12: =X12*AA12 -> 691044 | AC12: =IF(X12>0,ROUNDUP('前提条件'!$B$15/X12,0),"赤字") -> 362 | AD12: =T12+(X12-'前提条件'!$B$14*W12) -> 2264.176 | AE12: =J12+(X12-'前提条件'!$B$14*W12)/('前提条件'!$B$4*(1+'前提条件'!$B$5)*(1+U12)) -> 202.47593 | AF12: =IF(Y12>='前提条件'!$B$14,"◎ 15%以上",IF(Y12>='前提条件'!$B$16,"△ 条件付き","× 除外")) -> ◎ 15%以上 | AG12: リサーチ表に掲載（優先順位1）。置き配定着で需要が大きい戸建て用。組立式（ノックダウン）で梱包容積を完成品の約1/3に抑え、送料差で完成品の競合より高機能・同価格帯を実現 | AH12: https://store.shopping.yahoo.co.jp/tansu/17600169.html | AI12: 1688で検索 | AJ12: Amazonで検索
A13: 9 | B13: 3 | C13: 上位10 | D13: 猫トイレ収納キャビネット | E13: ペット用品 | F13: =IFERROR(INDEX('前提条件'!$B$20:$B$28,MATCH(E13,'前提条件'!$A$20:$A$28,0)),'前提条件'!$B$20) -> 0.154 | G13: 17980 | H13: アイリスオーヤマ CTC-890：Yahoo!¥13,336〜／楽天¥19,410、★4.18（22件） | I13: 19800 | J13: 170 | K13: 600 | L13: 105 | M13: 55 | N13: 18 | O13: 26 | P13: =L13+M13+N13 -> 178 | Q13: =L13*M13*N13/1000000 -> 0.10395 | R13: =MAX(MATCH(P13,'前提条件'!$C$34:$C$46,1),INDEX('前提条件'!$J$34:$J$41,MATCH(O13,'前提条件'!$H$34:$H$41,1))) -> 8 | S13: =INDEX('前提条件'!$B$34:$B$46,R13) -> 180サイズ | T13: =INDEX('前提条件'!$E$34:$E$46,R13)*'前提条件'!$B$7 -> 2200 | U13: 0 | V13: =J13*'前提条件'!$B$4*(1+'前提条件'!$B$5)+K13+Q13*'前提条件'!$B$6+(J13*'前提条件'!$B$4*(1+'前提条件'!$B$5)+Q13*'前提条件'!$B$6)*U13 -> 6253.8 | W13: =G13/(1+'前提条件'!$B$13) -> 16345.455 | X13: =W13*(1-'前提条件'!$B$8-'前提条件'!$B$9)-G13*F13-T13-Q13*'前提条件'!$B$10*'前提条件'!$B$11-'前提条件'!$B$12-V13 -> 2066.5959 | Y13: =IF(W13>0,X13/W13,0) -> 0.12643245 | Z13: =IF(W13>0,(X13+W13*'前提条件'!$B$8)/W13,0) -> 0.22643245 | AA13: 80 | AB13: =X13*AA13 -> 165327.67 | AC13: =IF(X13>0,ROUNDUP('前提条件'!$B$15/X13,0),"赤字") -> 484 | AD13: =T13+(X13-'前提条件'!$B$14*W13) -> 1814.7777 | AE13: =J13+(X13-'前提条件'!$B$14*W13)/('前提条件'!$B$4*(1+'前提条件'!$B$5)*(1+U13)) -> 155.13803 | AF13: =IF(Y13>='前提条件'!$B$14,"◎ 15%以上",IF(Y13>='前提条件'!$B$16,"△ 条件付き","× 除外")) -> △ 条件付き | AG13: 180サイズ送料と重い板材が利益を圧迫。仕入¥155元以下か国内送料¥1,815以下で15%到達。入口の狭さ・におい籠り・木部の水濡れが不満→防水トレー・換気口で差別化 | AH13: https://www.irisplaza.co.jp/index.php?KB=SHOSAI&SID=P288209F | AI13: 1688で検索 | AJ13: Amazonで検索
A14: 10 | B14: 27 | C14: 追加30 | D14: ロッド・釣具一体ラック | E14: スポーツ&アウトドア | F14: =IFERROR(INDEX('前提条件'!$B$20:$B$28,MATCH(E14,'前提条件'!$A$20:$A$28,0)),'前提条件'!$B$20) -> 0.104 | G14: 6980 | H14: 19本木製（日本製）、12本4in1（Yahoo!1位）等。価格未確認 | J14: 60 | K14: 200 | L14: 80 | M14: 40 | N14: 12 | O14: 7 | P14: =L14+M14+N14 -> 132 | Q14: =L14*M14*N14/1000000 -> 0.0384 | R14: =MAX(MATCH(P14,'前提条件'!$C$34:$C$46,1),INDEX('前提条件'!$J$34:$J$41,MATCH(O14,'前提条件'!$H$34:$H$41,1))) -> 5 | S14: =INDEX('前提条件'!$B$34:$B$46,R14) -> 140サイズ | T14: =INDEX('前提条件'!$E$34:$E$46,R14)*'前提条件'!$B$7 -> 1250 | U14: 0 | V14: =J14*'前提条件'!$B$4*(1+'前提条件'!$B$5)+K14+Q14*'前提条件'!$B$6+(J14*'前提条件'!$B$4*(1+'前提条件'!$B$5)+Q14*'前提条件'!$B$6)*U14 -> 2216 | W14: =G14/(1+'前提条件'!$B$13) -> 6345.4545 | X14: =W14*(1-'前提条件'!$B$8-'前提条件'!$B$9)-G14*F14-T14-Q14*'前提条件'!$B$10*'前提条件'!$B$11-'前提条件'!$B$12-V14 -> 792.37091 | Y14: =IF(W14>0,X14/W14,0) -> 0.12487221 | Z14: =IF(W14>0,(X14+W14*'前提条件'!$B$8)/W14,0) -> 0.22487221 | AA14: 60 | AB14: =X14*AA14 -> 47542.255 | AC14: =IF(X14>0,ROUNDUP('前提条件'!$B$15/X14,0),"赤字") -> 1263 | AD14: =T14+(X14-'前提条件'!$B$14*W14) -> 1090.5527 | AE14: =J14+(X14-'前提条件'!$B$14*W14)/('前提条件'!$B$4*(1+'前提条件'!$B$5)*(1+U14)) -> 53.848485 | AF14: =IF(Y14>='前提条件'!$B$14,"◎ 15%以上",IF(Y14>='前提条件'!$B$16,"△ 条件付き","× 除外")) -> △ 条件付き | AG14: 市場が小さい。タックル棚付きで¥7,980以上なら15%到達 | AH14: https://search.kakaku.com/%E3%83%AD%E3%83%83%E3%83%89%E3%82%B9%E3%82%BF%E3%83%B3%E3%83%89/ | AI14: 1688で検索 | AJ14: Amazonで検索
A15: 11 | B15: 20 | C15: 追加30 | D15: レイズドガーデンベッド | E15: DIY・工具・ガーデン | F15: =IFERROR(INDEX('前提条件'!$B$20:$B$28,MATCH(E15,'前提条件'!$A$20:$A$28,0)),'前提条件'!$B$20) -> 0.154 | G15: 7980 | H15: ohbien（120×60×28・亜鉛メッキ）、100×100×45が¥4,580の例 | J15: 70 | K15: 200 | L15: 95 | M15: 35 | N15: 10 | O15: 11 | P15: =L15+M15+N15 -> 140 | Q15: =L15*M15*N15/1000000 -> 0.03325 | R15: =MAX(MATCH(P15,'前提条件'!$C$34:$C$46,1),INDEX('前提条件'!$J$34:$J$41,MATCH(O15,'前提条件'!$H$34:$H$41,1))) -> 5 | S15: =INDEX('前提条件'!$B$34:$B$46,R15) -> 140サイズ | T15: =INDEX('前提条件'!$E$34:$E$46,R15)*'前提条件'!$B$7 -> 1250 | U15: 0 | V15: =J15*'前提条件'!$B$4*(1+'前提条件'!$B$5)+K15+Q15*'前提条件'!$B$6+(J15*'前提条件'!$B$4*(1+'前提条件'!$B$5)+Q15*'前提条件'!$B$6)*U15 -> 2413.4 | W15: =G15/(1+'前提条件'!$B$13) -> 7254.5455 | X15: =W15*(1-'前提条件'!$B$8-'前提条件'!$B$9)-G15*F15-T15-Q15*'前提条件'!$B$10*'前提条件'!$B$11-'前提条件'!$B$12-V15 -> 896.96409 | Y15: =IF(W15>0,X15/W15,0) -> 0.12364167 | Z15: =IF(W15>0,(X15+W15*'前提条件'!$B$8)/W15,0) -> 0.22364167 | AA15: 80 | AB15: =X15*AA15 -> 71757.127 | AC15: =IF(X15>0,ROUNDUP('前提条件'!$B$15/X15,0),"赤字") -> 1115 | AD15: =T15+(X15-'前提条件'!$B$14*W15) -> 1058.7823 | AE15: =J15+(X15-'前提条件'!$B$14*W15)/('前提条件'!$B$4*(1+'前提条件'!$B$5)*(1+U15)) -> 62.622773 | AF15: =IF(Y15>='前提条件'!$B$14,"◎ 15%以上",IF(Y15>='前提条件'!$B$16,"△ 条件付き","× 除外")) -> △ 条件付き | AG15: 価格競争が強い。防虫ネット支柱・散水チューブ付きセットで単価を上げれば15%到達の可能性 | AH15: https://www.amazon.co.jp/gp/bestsellers/diy/10472105051 | AI15: 1688で検索 | AJ15: Amazonで検索
A16: 12 | B16: 10 | C16: 上位10 | D16: 静音ステンレスワゴン | E16: 産業・研究開発用品 | F16: =IFERROR(INDEX('前提条件'!$B$20:$B$28,MATCH(E16,'前提条件'!$A$20:$A$28,0)),'前提条件'!$B$20) -> 0.154 | G16: 11980 | H16: Amazon 3段 ¥5,980〜11,980／柏ステンレス 静音 ¥37,650（価格.com） | I16: 17980 | J16: 120 | K16: 400 | L16: 80 | M16: 47 | N16: 15 | O16: 14 | P16: =L16+M16+N16 -> 142 | Q16: =L16*M16*N16/1000000 -> 0.0564 | R16: =MAX(MATCH(P16,'前提条件'!$C$34:$C$46,1),INDEX('前提条件'!$J$34:$J$41,MATCH(O16,'前提条件'!$H$34:$H$41,1))) -> 6 | S16: =INDEX('前提条件'!$B$34:$B$46,R16) -> 160サイズ | T16: =INDEX('前提条件'!$E$34:$E$46,R16)*'前提条件'!$B$7 -> 1450 | U16: 0 | V16: =J16*'前提条件'!$B$4*(1+'前提条件'!$B$5)+K16+Q16*'前提条件'!$B$6+(J16*'前提条件'!$B$4*(1+'前提条件'!$B$5)+Q16*'前提条件'!$B$6)*U16 -> 4187.2 | W16: =G16/(1+'前提条件'!$B$13) -> 10890.909 | X16: =W16*(1-'前提条件'!$B$8-'前提条件'!$B$9)-G16*F16-T16-Q16*'前提条件'!$B$10*'前提条件'!$B$11-'前提条件'!$B$12-V16 -> 1330.2618 | Y16: =IF(W16>0,X16/W16,0) -> 0.12214424 | Z16: =IF(W16>0,(X16+W16*'前提条件'!$B$8)/W16,0) -> 0.22214424 | AA16: 80 | AB16: =X16*AA16 -> 106420.95 | AC16: =IF(X16>0,ROUNDUP('前提条件'!$B$15/X16,0),"赤字") -> 752 | AD16: =T16+(X16-'前提条件'!$B$14*W16) -> 1146.6255 | AE16: =J16+(X16-'前提条件'!$B$14*W16)/('前提条件'!$B$4*(1+'前提条件'!$B$5)*(1+U16)) -> 108.29574 | AF16: =IF(Y16>='前提条件'!$B$14,"◎ 15%以上",IF(Y16>='前提条件'!$B$16,"△ 条件付き","× 除外")) -> △ 条件付き | AG16: 上限価格帯でしか成立しない。100mm静音キャスター＋棚マット＋バンパーで¥12,980以上を取れれば15%到達 | AH16: https://www.amazon.co.jp/dp/B074J5WJ36 | AI16: 1688で検索 | AJ16: Amazonで検索
A17: 13 | B17: 28 | C17: 追加30 | D17: 筋トレ用品収納ラック | E17: スポーツ&アウトドア | F17: =IFERROR(INDEX('前提条件'!$B$20:$B$28,MATCH(E17,'前提条件'!$A$20:$A$28,0)),'前提条件'!$B$20) -> 0.104 | G17: 19800 | H17: スチール3段・400kg等。価格未確認 | J17: 250 | K17: 400 | L17: 120 | M17: 50 | N17: 15 | O17: 38 | P17: =L17+M17+N17 -> 185 | Q17: =L17*M17*N17/1000000 -> 0.09 | R17: =MAX(MATCH(P17,'前提条件'!$C$34:$C$46,1),INDEX('前提条件'!$J$34:$J$41,MATCH(O17,'前提条件'!$H$34:$H$41,1))) -> 9 | S17: =INDEX('前提条件'!$B$34:$B$46,R17) -> 200サイズ | T17: =INDEX('前提条件'!$E$34:$E$46,R17)*'前提条件'!$B$7 -> 2700 | U17: 0 | V17: =J17*'前提条件'!$B$4*(1+'前提条件'!$B$5)+K17+Q17*'前提条件'!$B$6+(J17*'前提条件'!$B$4*(1+'前提条件'!$B$5)+Q17*'前提条件'!$B$6)*U17 -> 7960 | W17: =G17/(1+'前提条件'!$B$13) -> 18000 | X17: =W17*(1-'前提条件'!$B$8-'前提条件'!$B$9)-G17*F17-T17-Q17*'前提条件'!$B$10*'前提条件'!$B$11-'前提条件'!$B$12-V17 -> 2055.8 | Y17: =IF(W17>0,X17/W17,0) -> 0.11421111 | Z17: =IF(W17>0,(X17+W17*'前提条件'!$B$8)/W17,0) -> 0.21421111 | AA17: 40 | AB17: =X17*AA17 -> 82232 | AC17: =IF(X17>0,ROUNDUP('前提条件'!$B$15/X17,0),"赤字") -> 487 | AD17: =T17+(X17-'前提条件'!$B$14*W17) -> 2055.8 | AE17: =J17+(X17-'前提条件'!$B$14*W17)/('前提条件'!$B$4*(1+'前提条件'!$B$5)*(1+U17)) -> 225.1466 | AF17: =IF(Y17>='前提条件'!$B$14,"◎ 15%以上",IF(Y17>='前提条件'!$B$16,"△ 条件付き","× 除外")) -> △ 条件付き | AG17: 38kg・200サイズ。ホームジム需要は堅いが送料が重い | AH17: https://search.kakaku.com/%E3%83%80%E3%83%B3%E3%83%99%E3%83%AB%E3%83%A9%E3%83%83%E3%82%AF/ | AI17: 1688で検索 | AJ17: Amazonで検索
A18: 14 | B18: 18 | C18: 追加30 | D18: 大型観葉植物ラック | E18: DIY・工具・ガーデン | F18: =IFERROR(INDEX('前提条件'!$B$20:$B$28,MATCH(E18,'前提条件'!$A$20:$A$28,0)),'前提条件'!$B$20) -> 0.154 | G18: 6980 | H18: Yahoo! 6段¥3,980・4段¥6,980（検索結果） | J18: 50 | K18: 200 | L18: 90 | M18: 35 | N18: 12 | O18: 8 | P18: =L18+M18+N18 -> 137 | Q18: =L18*M18*N18/1000000 -> 0.0378 | R18: =MAX(MATCH(P18,'前提条件'!$C$34:$C$46,1),INDEX('前提条件'!$J$34:$J$41,MATCH(O18,'前提条件'!$H$34:$H$41,1))) -> 5 | S18: =INDEX('前提条件'!$B$34:$B$46,R18) -> 140サイズ | T18: =INDEX('前提条件'!$E$34:$E$46,R18)*'前提条件'!$B$7 -> 1250 | U18: 0 | V18: =J18*'前提条件'!$B$4*(1+'前提条件'!$B$5)+K18+Q18*'前提条件'!$B$6+(J18*'前提条件'!$B$4*(1+'前提条件'!$B$5)+Q18*'前提条件'!$B$6)*U18 -> 1949.6 | W18: =G18/(1+'前提条件'!$B$13) -> 6345.4545 | X18: =W18*(1-'前提条件'!$B$8-'前提条件'!$B$9)-G18*F18-T18-Q18*'前提条件'!$B$10*'前提条件'!$B$11-'前提条件'!$B$12-V18 -> 712.47091 | Y18: =IF(W18>0,X18/W18,0) -> 0.11228052 | Z18: =IF(W18>0,(X18+W18*'前提条件'!$B$8)/W18,0) -> 0.21228052 | AA18: 150 | AB18: =X18*AA18 -> 106870.64 | AC18: =IF(X18>0,ROUNDUP('前提条件'!$B$15/X18,0),"赤字") -> 1404 | AD18: =T18+(X18-'前提条件'!$B$14*W18) -> 1010.6527 | AE18: =J18+(X18-'前提条件'!$B$14*W18)/('前提条件'!$B$4*(1+'前提条件'!$B$5)*(1+U18)) -> 40.765923 | AF18: =IF(Y18>='前提条件'!$B$14,"◎ 15%以上",IF(Y18>='前提条件'!$B$16,"△ 条件付き","× 除外")) -> △ 条件付き | AG18: 低単価帯。育成ライト付きなど¥8,980以上で売れる仕様なら再評価 | AH18: https://shopping.yahoo.co.jp/search/%E8%A6%B3%E8%91%89%E6%A4%8D%E7%89%A9+%E3%83%A9%E3%83%83%E3%82%AF/0/ | AI18: 1688で検索 | AJ18: Amazonで検索
A19: 15 | B19: 4 | C19: 上位10 | D19: 業務用リネン回収カート | E19: 産業・研究開発用品 | F19: =IFERROR(INDEX('前提条件'!$B$20:$B$28,MATCH(E19,'前提条件'!$A$20:$A$28,0)),'前提条件'!$B$20) -> 0.154 | G19: 17800 | H19: PANCY 約400L（88×64×78・8本パイプ）等。価格未確認 | I19: 19800 | J19: 180 | K19: 500 | L19: 92 | M19: 62 | N19: 18 | O19: 14 | P19: =L19+M19+N19 -> 172 | Q19: =L19*M19*N19/1000000 -> 0.102672 | R19: =MAX(MATCH(P19,'前提条件'!$C$34:$C$46,1),INDEX('前提条件'!$J$34:$J$41,MATCH(O19,'前提条件'!$H$34:$H$41,1))) -> 8 | S19: =INDEX('前提条件'!$B$34:$B$46,R19) -> 180サイズ | T19: =INDEX('前提条件'!$E$34:$E$46,R19)*'前提条件'!$B$7 -> 2200 | U19: 0 | V19: =J19*'前提条件'!$B$4*(1+'前提条件'!$B$5)+K19+Q19*'前提条件'!$B$6+(J19*'前提条件'!$B$4*(1+'前提条件'!$B$5)+Q19*'前提条件'!$B$6)*U19 -> 6397.664 | W19: =G19/(1+'前提条件'!$B$13) -> 16181.818 | X19: =W19*(1-'前提条件'!$B$8-'前提条件'!$B$9)-G19*F19-T19-Q19*'前提条件'!$B$10*'前提条件'!$B$11-'前提条件'!$B$12-V19 -> 1815.4756 | Y19: =IF(W19>0,X19/W19,0) -> 0.11219231 | Z19: =IF(W19>0,(X19+W19*'前提条件'!$B$8)/W19,0) -> 0.21219231 | AA19: 40 | AB19: =X19*AA19 -> 72619.025 | AC19: =IF(X19>0,ROUNDUP('前提条件'!$B$15/X19,0),"赤字") -> 551 | AD19: =T19+(X19-'前提条件'!$B$14*W19) -> 1588.2029 | AE19: =J19+(X19-'前提条件'!$B$14*W19)/('前提条件'!$B$4*(1+'前提条件'!$B$5)*(1+U19)) -> 156.39672 | AF19: =IF(Y19>='前提条件'!$B$14,"◎ 15%以上",IF(Y19>='前提条件'!$B$16,"△ 条件付き","× 除外")) -> △ 条件付き | AG19: B2B（ホテル・民泊・介護）で単価は取れるが月販が小さい。交換用バッグ・キャスターの継続販売で補う。静音キャスターが選定ポイント | AH19: https://www.amazon.co.jp/dp/B0DDC8VVM2 | AI19: 1688で検索 | AJ19: Amazonで検索
A20: 16 | B20: 5 | C20: 上位10 | D20: 園芸用ポッティングベンチ | E20: DIY・工具・ガーデン | F20: =IFERROR(INDEX('前提条件'!$B$20:$B$28,MATCH(E20,'前提条件'!$A$20:$A$28,0)),'前提条件'!$B$20) -> 0.154 | G20: 17980 | H20: Yahoo! 36インチ木製¥17,243／天然木パネル型¥29,800〜34,800 | I20: 17980 | J20: 170 | K20: 400 | L20: 125 | M20: 55 | N20: 15 | O20: 20 | P20: =L20+M20+N20 -> 195 | Q20: =L20*M20*N20/1000000 -> 0.103125 | R20: =MAX(MATCH(P20,'前提条件'!$C$34:$C$46,1),INDEX('前提条件'!$J$34:$J$41,MATCH(O20,'前提条件'!$H$34:$H$41,1))) -> 9 | S20: =INDEX('前提条件'!$B$34:$B$46,R20) -> 200サイズ | T20: =INDEX('前提条件'!$E$34:$E$46,R20)*'前提条件'!$B$7 -> 2700 | U20: 0 | V20: =J20*'前提条件'!$B$4*(1+'前提条件'!$B$5)+K20+Q20*'前提条件'!$B$6+(J20*'前提条件'!$B$4*(1+'前提条件'!$B$5)+Q20*'前提条件'!$B$6)*U20 -> 6043.9 | W20: =G20/(1+'前提条件'!$B$13) -> 16345.455 | X20: =W20*(1-'前提条件'!$B$8-'前提条件'!$B$9)-G20*F20-T20-Q20*'前提条件'!$B$10*'前提条件'!$B$11-'前提条件'!$B$12-V20 -> 1780.2084 | Y20: =IF(W20>0,X20/W20,0) -> 0.10891153 | Z20: =IF(W20>0,(X20+W20*'前提条件'!$B$8)/W20,0) -> 0.20891153 | AA20: 40 | AB20: =X20*AA20 -> 71208.336 | AC20: =IF(X20>0,ROUNDUP('前提条件'!$B$15/X20,0),"赤字") -> 562 | AD20: =T20+(X20-'前提条件'!$B$14*W20) -> 2028.3902 | AE20: =J20+(X20-'前提条件'!$B$14*W20)/('前提条件'!$B$4*(1+'前提条件'!$B$5)*(1+U20)) -> 144.08913 | AF20: =IF(Y20>='前提条件'!$B$14,"◎ 15%以上",IF(Y20>='前提条件'!$B$16,"△ 条件付き","× 除外")) -> △ 条件付き | AG20: 200サイズ送料。防腐処理・亜鉛天板トレー等で¥19,800以上を取れれば再評価。組立の複雑さ・防腐が不満点 | AH20: https://www.amazon.co.jp/dp/B0D9GJ5W3W | AI20: 1688で検索 | AJ20: Amazonで検索
A21: 17 | B21: 15 | C21: 追加30 | D21: 頑丈ハンガーラック | E21: ホーム&キッチン | F21: =IFERROR(INDEX('前提条件'!$B$20:$B$28,MATCH(E21,'前提条件'!$A$20:$A$28,0)),'前提条件'!$B$20) -> 0.154 | G21: 7980 | H21: 山善 MKS-WS（幅86-140伸縮）、ストロンガー HR-120（100kg）等。価格未確認 | J21: 75 | K21: 200 | L21: 122 | M21: 16 | N21: 12 | O21: 11 | P21: =L21+M21+N21 -> 150 | Q21: =L21*M21*N21/1000000 -> 0.023424 | R21: =MAX(MATCH(P21,'前提条件'!$C$34:$C$46,1),INDEX('前提条件'!$J$34:$J$41,MATCH(O21,'前提条件'!$H$34:$H$41,1))) -> 6 | S21: =INDEX('前提条件'!$B$34:$B$46,R21) -> 160サイズ | T21: =INDEX('前提条件'!$E$34:$E$46,R21)*'前提条件'!$B$7 -> 1450 | U21: 0 | V21: =J21*'前提条件'!$B$4*(1+'前提条件'!$B$5)+K21+Q21*'前提条件'!$B$6+(J21*'前提条件'!$B$4*(1+'前提条件'!$B$5)+Q21*'前提条件'!$B$6)*U21 -> 2425.088 | W21: =G21/(1+'前提条件'!$B$13) -> 7254.5455 | X21: =W21*(1-'前提条件'!$B$8-'前提条件'!$B$9)-G21*F21-T21-Q21*'前提条件'!$B$10*'前提条件'!$B$11-'前提条件'!$B$12-V21 -> 729.49309 | Y21: =IF(W21>0,X21/W21,0) -> 0.10055669 | Z21: =IF(W21>0,(X21+W21*'前提条件'!$B$8)/W21,0) -> 0.20055669 | AA21: 200 | AB21: =X21*AA21 -> 145898.62 | AC21: =IF(X21>0,ROUNDUP('前提条件'!$B$15/X21,0),"赤字") -> 1371 | AD21: =T21+(X21-'前提条件'!$B$14*W21) -> 1091.3113 | AE21: =J21+(X21-'前提条件'!$B$14*W21)/('前提条件'!$B$4*(1+'前提条件'!$B$5)*(1+U21)) -> 61.1617 | AF21: =IF(Y21>='前提条件'!$B$14,"◎ 15%以上",IF(Y21>='前提条件'!$B$16,"△ 条件付き","× 除外")) -> △ 条件付き | AG21: 国内大手（山善・アイリス）が強く単価が上がらない。業務用100kg超・高さ調整12段で¥8,980以上なら再評価 | AH21: https://www.amazon.co.jp/dp/B0C9CMC968 | AI21: 1688で検索 | AJ21: Amazonで検索
